Workbook

Sheet INFO UPDATE EXCEL
C3: INFO UPDATE EXCEL
C4: v4.0
C5: - menambah perhitungan progesif pph 21
C6: - menyatukan perhitungan pph 4 (2)
C7: - menambah perhitungan pph 22 jika belanja di Markeplace pemerintah (SIPP)
C9: v4.1
C10: - revisi tarif belanja di MARKETPLACE PEMERINTAH
C12: v5.0
C13: - Update Info Pajak : Jenis dan kode bayar ID Billing
C15: v6.0
C16: - Update info pajak : Objek Pajak yang Dikecualikan
C18: v6.1
... C25: - Update PPN DPP 11/12 dan tarif 12%

Sheet INFO PAJAK
B1: INFO PAJAK BUAT E BILLING | I1: YANG DIKENAKAN DAN DIKECUALIKAN PAJAK, PMK No.231/PMK.03/2019
I2: PPN
B3: Catatan | I3: DIKECUALIKAN
B4: PPN | C4: Transaksi lebih dari 2 juta | I4: 1. JIKA ORANG PRIBADI ADALAH NON PKP, MAKA TIDAK DIKENAKAN PPN
B5: PPh 22 | C5: Transaksi lebih dari 2 juta | I5: 2. dll sbg berikut
B6: PPh 23 | C6: Tidak ada batasan transaksi
I7: a. pembayaran yang jumlahnya paling banyak
B8: PMK NOMOR 59 TAHUN 2022 | I8: Rp2.000.000,00 (dua juta rupiah) tidak termasuk
B9: NAMA YANG TERCANTUM DALAM E BILLING | I9: jumlah PPN atau PPN dan PPnBM yang terutang, dan
B10: NO | C10: JENIS | D10: PENYETORAN | I10: bukan merupakan pembayaran yang dipecah dari suatu
B11: 1 | C11: PPh Pasal 4 Ayat 2 (Persewaan Tanah dan/atau Bangunan) | D11: atas nama Instansi Pemerintah | I11: transaksi yang nilai sebenarnya lebih dari
B12: 2 | C12: PPh Pasal 4 Ayat 2 (Pengalihan Hak atas Tanah dan/atau Bangunan) | D12: atas nama Orang Pribadi/Badan yang menerima pembayaran | I12: Rp2.000.000,00 (duajuta rupiah);
B13: 3 | C13: PPh pasal 4 Ayat 2 (Usaha Jasa Konstruksi) | D13: atas nama Instansi Pemerintah
B14: 4 | C14: PPh Pasal 4 Ayat 2 (Hadiah Undian) | D14: atas nama Instansi Pemerintah | I14: b. pembayaran dengan kartu kredit pemerintah atas
B15: 5 | C15: PPh Pasal 15 | D15: atas nama Instansi Pemerintah | I15: belanja Instansi Pemerintah Pusat sesua1 ketentuan
B16: 6 | C16: PPh Pasal 22 | D16: atas nama Rekanan Pemerintah | I16: peraturan perundang-undangan yang mengatur
B17: 7 | C17: PPh Pasal 23 | D17: atas nama Instansi Pemerintah | I17: mengenai tata cara pembayaran dan penggunaan kartu
B18: 8 | C18: PPN | D18: atas nama Instansi Pemerintah | I18: kredit pemerintah;
I20: c. pembayaran untuk pengadaan tanah;
C22: JENIS PAJAK | I22: d. pembayaran atas penyerahan bahan bakar minyak dan
I23: bahan bakar bukan minyak oleh PT Pertamina
I24: (Persero);
D26: 411121 | E26: PPh 21 | I26: e. pembayaran atas penyerahan jasa telekomunikasi oleh
D27: 411122 | E27: PPh 22 | I27: perusahaan telekomunikasi;
D28: 411124 | E28: PPh 23
D29: 411128 | E29: PPh Final | I29: f. pembayaran atas jasa angkutan udara yang diserahkan
D30: 411211 | E30: PPN Dalam Negeri | I30: oleh perusahaan penerbangan; dan/ atau
D31: 411219 | E31: PPN Lainnya
D32: 411221 | E32: PPN BM Dalam Negeri | I32: g. pembayaran atas penyerahan Barang Kena Pajak
I33: dan/atau Jasa Kena Pajak yang menurut ketentuan
I34: perundang-undangan di bidang perpajakan, mendapat
I35: fasilitas PPN tidak dipungut atau dibebaskan dari
I36: pengenaan PPN.
I38: PPH 21
I39: DIKECUALIKAN
I41: (2) Instansi Pemerintah tidak melakukan pemotongan PPh Pasal
I42: 21 sebagaimana dimaksud pada ayat (1) atas:
I44: a. pembayaran kepada Wajib Pajak yang memiliki dan
C45: JENIS SETORAN PPN | I45: menyerahkan fotokopi surat keterangan berdasarkan
I46: Peraturan Pemerintah yang mengatur tentang PPh atas
...

Sheet TARIF PAJAK
A1: PPh 21
A2: No | B2: Uraian | C2: Tarif PPh 21 | D2: Kode Objek Pajak | E2: Keterangan
A3: 1 | B3: Honorarium Yang Berasal dari APBD (Final) | E3: DPP PPh 21 = 100%, Honorarium apapun, termasuk uang saku, uang lembur, Honor Narsum dll. (Diterima oleh ASN)
B4: - Gol. II | C4: 0 | D4: 21-402-01
B5: - Gol. III | C5: 0.05 | D5: 21-402-01
B6: - Gol. IV | C6: 0.15 | D6: 21-402-01
A7: 2 | B7: Jasa Tenaga Ahli (Dokter, pengacara, dan akuntan, yang melakukan pekerjaan bebas dan bertindak untuk dan atas namanya sendiri, bukan untuk dan atas nama persekutuannya. | C7: 5%-35% progesif | D7: 21-100-07 | E7: DPP PPh 21 = Penghasilan Bruto x 50%
A8: 3 | B8: Narasumber, Moderator, Pembicara | C8: 5%-35% progesif | D8: 21-100-09 | E8: DPP PPh 21 = Penghasilan Bruto x 50%
A9: 4 | B9: Jasa Artis (Tanpa Melalui Manajemen) | C9: 5%-35% progesif | D9: 21-100-09 | E9: DPP PPh 21 = Penghasilan Bruto x 50%
A10: 5 | B10: Jasa Dokumentasi dan Publikasi (Perorangan) | C10: 5%-35% progesif | D10: 21-100-09 | E10: DPP PPh 21 = Penghasilan Bruto x 50%
A11: 6 | B11: Peserta kegiatan/Menerima hadiah | C11: 5%-35% progesif | D11: 21-100-09 | E11: DPP PPh 21 = 100%
A12: 7 | B12: Penghargaan Gubernur kepada Perorangan | C12: 5%-35% progesif | D12: 21-100-99 | E12: DPP PPh 21 = 100%
A13: 8 | B13: Jasa lain yang disediakan oleh Orang Pribadi | C13: 5%-35% progesif | D13: 21-100-99 | E13: DPP PPh 21 = 100%
C16: Progesif PPh 21
C17: DPP | D17: Tarif
C18: 0-60jt | D18: 0.05
C19: 60jt-250jt | D19: 0.15
C20: 250jt-500jt | D20: 0.25
C21: 500jt-5M | D21: 0.3
C22: >5M | D22: 0.35
A24: PPN, PPh 22, dan PPh 23 | C24: DPP menjadi 11/12
A25: No | B25: Uraian | C25: Tarif PPN | D25: Tarif PPh 22 | E25: Tarif PPh 23 | F25: Kode Objek Pajak
A26: 1 | B26: Pembelian barang, ATK | C26: 0.12 | D26: 0.015 | E26: - | F26: 22-920-01
A27: 2 | B27: Makanan dan Minuman
B28: 1. - Belanja makan minum dengan menggunakan jasa katering | C28: - | D28: - | E28: 0.02 | F28: 24-104-39 | G28: Contohnya : Jasa Catering makanan
B29: 2. - Belanja makan minum yang disajikan di restoran, hotel, warung, rumah makan, dan semacamnya | C29: - | D29: 0.015 | E29: - | F29: 22-920-01 | G29: Contohnya : belanja di Restoran Ampera, KFC dll
B30: 3. - Belanja makanan dan minuman di minimarket atau semacamnya | C30: 0.12 | D30: 0.015 | E30: - | G30: Contohnya : beli makanan dalam kemasan di Indomaret, Alfamaret, dll
A31: 3 | B31: Pakaian
B32: - Beli jadi | C32: 0.12 | D32: 0.015 | E32: - | F32: 22-920-01
B33: - Jasa Maklon | C33: 0.12 | D33: - | E33: 0.02 | F33: 24-104-31
A34: 4 | B34: Plakat/Vandel/Piala/Cinderamata/Souvenir | C34: 0.12 | D34: 0.015 | E34: - | F34: 22-920-01
A35: 5 | B35: Dokumentasi dan Publikasi (PT,CV,Firma) | C35: 0.12 | D35: - | E35: 0.02 | F35: 24-104-65
A36: 6 | B36: Jasa Penyelenggaraan/EO | C36: 0.12 | D36: - | E36: 0.02 | F36: 24-104-33
A37: 7 | B37: Pencetakan/penerbitan (Surat Kabar) | C37: 0.12 | D37: - | E37: 0.02 | F37: 24-104-54
A38: 8 | B38: Penjilidan/Fotocopy | C38: 0.12 | E38: 0.02 | F38: 24-104-65
A39: 9 | B39: Jasa Dekorasi | C39: 0.12 | D39: - | E39: 0.02 | F39: 24-104-53
A40: 10 | B40: Jasa Keamanan | C40: 0.12 | D40: - | E40: 0.02 | F40: 24-104-32
A41: 11 | B41: Jasa Kebersihan/Cleaning service | C41: 0.12 | D41: - | E41: 0.02 | F41: 24-104-36
A42: 12 | B42: Jasa Konsultasi (Selain Konstruksi) | C42: 0.12 | D42: - | E42: 0.02 | F42: 24-104-03
A43: 13 | B43: Jasa Travel | C43: 0.12 | D43: - | E43: 0.02 | F43: 24-104-18
...

Sheet TER pph 21
N1: 1 | Q1: ="PEGAWAI KE "&N1 -> PEGAWAI KE 1 | Y1: =1+N1 -> 2 | AB1: ="PEGAWAI KE "&Y1 -> PEGAWAI KE 2 | AJ1: =1+Y1 -> 3 | AM1: ="PEGAWAI KE "&AJ1 -> PEGAWAI KE 3 | AU1: =1+AJ1 -> 4 | AX1: ="PEGAWAI KE "&AU1 -> PEGAWAI KE 4 | BF1: =1+AU1 -> 5 | BI1: ="PEGAWAI KE "&BF1 -> PEGAWAI KE 5 | BQ1: =1+BF1 -> 6 | BT1: ="PEGAWAI KE "&BQ1 -> PEGAWAI KE 6 | CB1: =1+BQ1 -> 7 | CE1: ="PEGAWAI KE "&CB1 -> PEGAWAI KE 7 | CM1: =1+CB1 -> 8 | CP1: ="PEGAWAI KE "&CM1 -> PEGAWAI KE 8 | CX1: =1+CM1 -> 9 | DA1: ="PEGAWAI KE "&CX1 -> PEGAWAI KE 9 | DI1: =1+CX1 -> 10 | DL1: ="PEGAWAI KE "&DI1 -> PEGAWAI KE 10
O2: =_xlfn.XLOOKUP(Q1,$C:$C,$D:$D) -> TER A: TK/0 TK/1 K/0 | P2: =_xlfn.XLOOKUP(Q1,$C:$C,$E:$E) -> 10000000 | Q2: =SUM(W4:W129) -> 0.02 | Z2: =_xlfn.XLOOKUP(AB1,$C:$C,$D:$D) -> TER B: TK/2 TK/3 K/1 K/2 | AA2: =_xlfn.XLOOKUP(AB1,$C:$C,$E:$E) -> 15000000 | AB2: =SUM(AH4:AH129) -> 0.06 | AK2: =_xlfn.XLOOKUP(AM1,$C:$C,$D:$D) -> TER C: K/3 | AL2: =_xlfn.XLOOKUP(AM1,$C:$C,$E:$E) -> 20000000 | AM2: =SUM(AS4:AS129) -> 0.08 | AV2: =_xlfn.XLOOKUP(AX1,$C:$C,$D:$D) -> TER A: TK/0 TK/1 K/0 | AW2: =_xlfn.XLOOKUP(AX1,$C:$C,$E:$E) -> 25000000 | AX2: =SUM(BD4:BD129) -> 0.1 | BG2: =_xlfn.XLOOKUP(BI1,$C:$C,$D:$D) -> TER B: TK/2 TK/3 K/1 K/2 | BH2: =_xlfn.XLOOKUP(BI1,$C:$C,$E:$E) -> 30000000 | BI2: =SUM(BO4:BO129) -> 0.12 | BR2: =_xlfn.XLOOKUP(BT1,$C:$C,$D:$D) -> TER C: K/3 | BS2: =_xlfn.XLOOKUP(BT1,$C:$C,$E:$E) -> 35000000 | BT2: =SUM(BZ4:BZ129) -> 0.14 | CC2: =_xlfn.XLOOKUP(CE1,$C:$C,$D:$D) -> TER A: TK/0 TK/1 K/0 | CD2: =_xlfn.XLOOKUP(CE1,$C:$C,$E:$E) -> 40000000 | CE2: =SUM(CK4:CK129) -> 0.16 | CN2: =_xlfn.XLOOKUP(CP1,$C:$C,$D:$D) -> TER B: TK/2 TK/3 K/1 K/2 | CO2: =_xlfn.XLOOKUP(CP1,$C:$C,$E:$E) -> 45000000 | CP2: =SUM(CV4:CV129) -> 0.16 | CY2: =_xlfn.XLOOKUP(DA1,$C:$C,$D:$D) -> TER C: K/3 | CZ2: =_xlfn.XLOOKUP(DA1,$C:$C,$E:$E) -> 50000000 | DA2: =SUM(DG4:DG129) -> 0.18 | DJ2: =_xlfn.XLOOKUP(DL1,$C:$C,$D:$D) -> TER A: TK/0 TK/1 K/0 | DK2: =_xlfn.XLOOKUP(DL1,$C:$C,$E:$E) -> 55000000 | DL2: =SUM(DR4:DR129) -> 0.19
C3: PEGAWAI | D3: PTKP | E3: PENGHASILAN BRUTO PERBULAN | F3: % | G3: PPh 21 | N3: No | O3: Lapisan Penghasilan Bruto (Rp) | R3: TER A | S3: CEK PTKP | T3: CEK MIN | U3: CEK MAKS | V3: TARIF | Y3: No | Z3: Lapisan Penghasilan Bruto (Rp) | AC3: TER A | AD3: CEK PTKP | AE3: CEK MIN | AF3: CEK MAKS | AG3: TARIF | AJ3: No | AK3: Lapisan Penghasilan Bruto (Rp) | AN3: TER A | AO3: CEK PTKP | AP3: CEK MIN | AQ3: CEK MAKS | AR3: TARIF | AU3: No | AV3: Lapisan Penghasilan Bruto (Rp) | AY3: TER A | AZ3: CEK PTKP | BA3: CEK MIN | BB3: CEK MAKS | BC3: TARIF | BF3: No | BG3: Lapisan Penghasilan Bruto (Rp) | BJ3: TER A | BK3: CEK PTKP | BL3: CEK MIN | BM3: CEK MAKS | BN3: TARIF | BQ3: No | BR3: Lapisan Penghasilan Bruto (Rp) | BU3: TER A | BV3: CEK PTKP | BW3: CEK MIN | BX3: CEK MAKS | BY3: TARIF | CB3: No | CC3: Lapisan Penghasilan Bruto (Rp) | CF3: TER A | CG3: CEK PTKP | CH3: CEK MIN | CI3: CEK MAKS | CJ3: TARIF | CM3: No | CN3: Lapisan Penghasilan Bruto (Rp) | CQ3: TER A | CR3: CEK PTKP | CS3: CEK MIN | CT3: CEK MAKS | CU3: TARIF | CX3: No | CY3: Lapisan Penghasilan Bruto (Rp) | DB3: TER A | DC3: CEK PTKP | DD3: CEK MIN | DE3: CEK MAKS | DF3: TARIF | DI3: No | DJ3: Lapisan Penghasilan Bruto (Rp) | DM3: TER A | DN3: CEK PTKP | DO3: CEK MIN | DP3: CEK MAKS | DQ3: TARIF
C4: PEGAWAI KE 1 | D4: TER A: TK/0 TK/1 K/0 | E4: =10000000 -> 10000000 | F4: =SUMIFS($2:$2,$1:$1,C4) -> 0.02 | G4: =E4*F4 -> 200000 | N4: TER A: TK/0 TK/1 K/0 | O4: 0 | P4: s.d. | Q4: 5400000 | R4: 0 | S4: =IF(N4=O$2,"OK","") -> OK | T4: =IF(P$2>=O4,"OK","") -> OK | U4: =IF(P$2<=Q4,"OK","") | V4: =S4&T4&U4 -> OKOK | W4: =IF(V4="OKOKOK",R4,0) -> 0 | Y4: TER A: TK/0 TK/1 K/0 | Z4: 0 | AA4: s.d. | AB4: 5400000 | AC4: 0 | AD4: =IF(Y4=Z$2,"OK","") | AE4: =IF(AA$2>=Z4,"OK","") -> OK | AF4: =IF(AA$2<=AB4,"OK","") | AG4: =AD4&AE4&AF4 -> OK | AH4: =IF(AG4="OKOKOK",AC4,0) -> 0 | AJ4: TER A: TK/0 TK/1 K/0 | AK4: 0 | AL4: s.d. | AM4: 5400000 | AN4: 0 | AO4: =IF(AJ4=AK$2,"OK","") | AP4: =IF(AL$2>=AK4,"OK","") -> OK | AQ4: =IF(AL$2<=AM4,"OK","") | AR4: =AO4&AP4&AQ4 -> OK | AS4: =IF(AR4="OKOKOK",AN4,0) -> 0 | AU4: TER A: TK/0 TK/1 K/0 | AV4: 0 | AW4: s.d. | AX4: 5400000 | AY4: 0 | AZ4: =IF(AU4=AV$2,"OK","") -> OK | BA4: =IF(AW$2>=AV4,"OK","") -> OK | BB4: =IF(AW$2<=AX4,"OK","") | BC4: =AZ4&BA4&BB4 -> OKOK | BD4: =IF(BC4="OKOKOK",AY4,0) -> 0 | BF4: TER A: TK/0 TK/1 K/0 | BG4: 0 | BH4: s.d. | BI4: 5400000 | BJ4: 0 | BK4: =IF(BF4=BG$2,"OK","") | BL4: =IF(BH$2>=BG4,"OK","") -> OK | BM4: =IF(BH$2<=BI4,"OK","") | BN4: =BK4&BL4&BM4 -> OK | BO4: =IF(BN4="OKOKOK",BJ4,0) -> 0 | BQ4: TER A: TK/0 TK/1 K/0 | BR4: 0 | BS4: s.d. | BT4: 5400000 | BU4: 0 | BV4: =IF(BQ4=BR$2,"OK","") | BW4: =IF(BS$2>=BR4,"OK","") -> OK | BX4: =IF(BS$2<=BT4,"OK","") | BY4: =BV4&BW4&BX4 -> OK | BZ4: =IF(BY4="OKOKOK",BU4,0) -> 0 | CB4: TER A: TK/0 TK/1 K/0 | CC4: 0 | CD4: s.d. | CE4: 5400000 | CF4: 0 | CG4: =IF(CB4=CC$2,"OK","") -> OK | CH4: =IF(CD$2>=CC4,"OK","") -> OK | CI4: =IF(CD$2<=CE4,"OK","") | CJ4: =CG4&CH4&CI4 -> OKOK | CK4: =IF(CJ4="OKOKOK",CF4,0) -> 0 | CM4: TER A: TK/0 TK/1 K/0 | CN4: 0 | CO4: s.d. | CP4: 5400000 | CQ4: 0 | CR4: =IF(CM4=CN$2,"OK","") | CS4: =IF(CO$2>=CN4,"OK","") -> OK | CT4: =IF(CO$2<=CP4,"OK","") | CU4: =CR4&CS4&CT4 -> OK | CV4: =IF(CU4="OKOKOK",CQ4,0) -> 0 | CX4: TER A: TK/0 TK/1 K/0 | CY4: 0 | CZ4: s.d. | DA4: 5400000 | DB4: 0 | DC4: =IF(CX4=CY$2,"OK","") | DD4: =IF(CZ$2>=CY4,"OK","") -> OK | DE4: =IF(CZ$2<=DA4,"OK","") | DF4: =DC4&DD4&DE4 -> OK | DG4: =IF(DF4="OKOKOK",DB4,0) -> 0 | DI4: TER A: TK/0 TK/1 K/0 | DJ4: 0 | DK4: s.d. | DL4: 5400000 | DM4: 0 | DN4: =IF(DI4=DJ$2,"OK","") -> OK | DO4: =IF(DK$2>=DJ4,"OK","") -> OK | DP4: =IF(DK$2<=DL4,"OK","") | DQ4: =DN4&DO4&DP4 -> OKOK | DR4: =IF(DQ4="OKOKOK",DM4,0) -> 0
C5: PEGAWAI KE 2 | D5: TER B: TK/2 TK/3 K/1 K/2 | E5: =E4+5000000 -> 15000000 | F5: =SUMIFS($2:$2,$1:$1,C5) -> 0.06 | G5: =E5*F5 -> 900000 | N5: TER A: TK/0 TK/1 K/0 | O5: 5400001 | P5: s.d. | Q5: 5650000 | R5: 0.0025 | S5: =IF(N5=O$2,"OK","") -> OK | T5: =IF(P$2>=O5,"OK","") -> OK | U5: =IF(P$2<=Q5,"OK","") | V5: =S5&T5&U5 -> OKOK | W5: =IF(V5="OKOKOK",R5,0) -> 0 | Y5: TER A: TK/0 TK/1 K/0 | Z5: 5400001 | AA5: s.d. | AB5: 5650000 | AC5: 0.0025 | AD5: =IF(Y5=Z$2,"OK","") | AE5: =IF(AA$2>=Z5,"OK","") -> OK | AF5: =IF(AA$2<=AB5,"OK","") | AG5: =AD5&AE5&AF5 -> OK | AH5: =IF(AG5="OKOKOK",AC5,0) -> 0 | AJ5: TER A: TK/0 TK/1 K/0 | AK5: 5400001 | AL5: s.d. | AM5: 5650000 | AN5: 0.0025 | AO5: =IF(AJ5=AK$2,"OK","") | AP5: =IF(AL$2>=AK5,"OK","") -> OK | AQ5: =IF(AL$2<=AM5,"OK","") | AR5: =AO5&AP5&AQ5 -> OK | AS5: =IF(AR5="OKOKOK",AN5,0) -> 0 | AU5: TER A: TK/0 TK/1 K/0 | AV5: 5400001 | AW5: s.d. | AX5: 5650000 | AY5: 0.0025 | AZ5: =IF(AU5=AV$2,"OK","") -> OK | BA5: =IF(AW$2>=AV5,"OK","") -> OK | BB5: =IF(AW$2<=AX5,"OK","") | BC5: =AZ5&BA5&BB5 -> OKOK | BD5: =IF(BC5="OKOKOK",AY5,0) -> 0 | BF5: TER A: TK/0 TK/1 K/0 | BG5: 5400001 | BH5: s.d. | BI5: 5650000 | BJ5: 0.0025 | BK5: =IF(BF5=BG$2,"OK","") | BL5: =IF(BH$2>=BG5,"OK","") -> OK | BM5: =IF(BH$2<=BI5,"OK","") | BN5: =BK5&BL5&BM5 -> OK | BO5: =IF(BN5="OKOKOK",BJ5,0) -> 0 | BQ5: TER A: TK/0 TK/1 K/0 | BR5: 5400001 | BS5: s.d. | BT5: 5650000 | BU5: 0.0025 | BV5: =IF(BQ5=BR$2,"OK","") | BW5: =IF(BS$2>=BR5,"OK","") -> OK | BX5: =IF(BS$2<=BT5,"OK","") | BY5: =BV5&BW5&BX5 -> OK | BZ5: =IF(BY5="OKOKOK",BU5,0) -> 0 | CB5: TER A: TK/0 TK/1 K/0 | CC5: 5400001 | CD5: s.d. | CE5: 5650000 | CF5: 0.0025 | CG5: =IF(CB5=CC$2,"OK","") -> OK | CH5: =IF(CD$2>=CC5,"OK","") -> OK | CI5: =IF(CD$2<=CE5,"OK","") | CJ5: =CG5&CH5&CI5 -> OKOK | CK5: =IF(CJ5="OKOKOK",CF5,0) -> 0 | CM5: TER A: TK/0 TK/1 K/0 | CN5: 5400001 | CO5: s.d. | CP5: 5650000 | CQ5: 0.0025 | CR5: =IF(CM5=CN$2,"OK","") | CS5: =IF(CO$2>=CN5,"OK","") -> OK | CT5: =IF(CO$2<=CP5,"OK","") | CU5: =CR5&CS5&CT5 -> OK | CV5: =IF(CU5="OKOKOK",CQ5,0) -> 0 | CX5: TER A: TK/0 TK/1 K/0 | CY5: 5400001 | CZ5: s.d. | DA5: 5650000 | DB5: 0.0025 | DC5: =IF(CX5=CY$2,"OK","") | DD5: =IF(CZ$2>=CY5,"OK","") -> OK | DE5: =IF(CZ$2<=DA5,"OK","") | DF5: =DC5&DD5&DE5 -> OK | DG5: =IF(DF5="OKOKOK",DB5,0) -> 0 | DI5: TER A: TK/0 TK/1 K/0 | DJ5: 5400001 | DK5: s.d. | DL5: 5650000 | DM5: 0.0025 | DN5: =IF(DI5=DJ$2,"OK","") -> OK | DO5: =IF(DK$2>=DJ5,"OK","") -> OK | DP5: =IF(DK$2<=DL5,"OK","") | DQ5: =DN5&DO5&DP5 -> OKOK | DR5: =IF(DQ5="OKOKOK",DM5,0) -> 0
C6: PEGAWAI KE 3 | D6: TER C: K/3 | E6: =E5+5000000 -> 20000000 | F6: =SUMIFS($2:$2,$1:$1,C6) -> 0.08 | G6: =E6*F6 -> 1600000 | N6: TER A: TK/0 TK/1 K/0 | O6: 5650001 | P6: s.d. | Q6: 5950000 | R6: 0.005 | S6: =IF(N6=O$2,"OK","") -> OK | T6: =IF(P$2>=O6,"OK","") -> OK | U6: =IF(P$2<=Q6,"OK","") | V6: =S6&T6&U6 -> OKOK | W6: =IF(V6="OKOKOK",R6,0) -> 0 | Y6: TER A: TK/0 TK/1 K/0 | Z6: 5650001 | AA6: s.d. | AB6: 5950000 | AC6: 0.005 | AD6: =IF(Y6=Z$2,"OK","") | AE6: =IF(AA$2>=Z6,"OK","") -> OK | AF6: =IF(AA$2<=AB6,"OK","") | AG6: =AD6&AE6&AF6 -> OK | AH6: =IF(AG6="OKOKOK",AC6,0) -> 0 | AJ6: TER A: TK/0 TK/1 K/0 | AK6: 5650001 | AL6: s.d. | AM6: 5950000 | AN6: 0.005 | AO6: =IF(AJ6=AK$2,"OK","") | AP6: =IF(AL$2>=AK6,"OK","") -> OK | AQ6: =IF(AL$2<=AM6,"OK","") | AR6: =AO6&AP6&AQ6 -> OK | AS6: =IF(AR6="OKOKOK",AN6,0) -> 0 | AU6: TER A: TK/0 TK/1 K/0 | AV6: 5650001 | AW6: s.d. | AX6: 5950000 | AY6: 0.005 | AZ6: =IF(AU6=AV$2,"OK","") -> OK | BA6: =IF(AW$2>=AV6,"OK","") -> OK | BB6: =IF(AW$2<=AX6,"OK","") | BC6: =AZ6&BA6&BB6 -> OKOK | BD6: =IF(BC6="OKOKOK",AY6,0) -> 0 | BF6: TER A: TK/0 TK/1 K/0 | BG6: 5650001 | BH6: s.d. | BI6: 5950000 | BJ6: 0.005 | BK6: =IF(BF6=BG$2,"OK","") | BL6: =IF(BH$2>=BG6,"OK","") -> OK | BM6: =IF(BH$2<=BI6,"OK","") | BN6: =BK6&BL6&BM6 -> OK | BO6: =IF(BN6="OKOKOK",BJ6,0) -> 0 | BQ6: TER A: TK/0 TK/1 K/0 | BR6: 5650001 | BS6: s.d. | BT6: 5950000 | BU6: 0.005 | BV6: =IF(BQ6=BR$2,"OK","") | BW6: =IF(BS$2>=BR6,"OK","") -> OK | BX6: =IF(BS$2<=BT6,"OK","") | BY6: =BV6&BW6&BX6 -> OK | BZ6: =IF(BY6="OKOKOK",BU6,0) -> 0 | CB6: TER A: TK/0 TK/1 K/0 | CC6: 5650001 | CD6: s.d. | CE6: 5950000 | CF6: 0.005 | CG6: =IF(CB6=CC$2,"OK","") -> OK | CH6: =IF(CD$2>=CC6,"OK","") -> OK | CI6: =IF(CD$2<=CE6,"OK","") | CJ6: =CG6&CH6&CI6 -> OKOK | CK6: =IF(CJ6="OKOKOK",CF6,0) -> 0 | CM6: TER A: TK/0 TK/1 K/0 | CN6: 5650001 | CO6: s.d. | CP6: 5950000 | CQ6: 0.005 | CR6: =IF(CM6=CN$2,"OK","") | CS6: =IF(CO$2>=CN6,"OK","") -> OK | CT6: =IF(CO$2<=CP6,"OK","") | CU6: =CR6&CS6&CT6 -> OK | CV6: =IF(CU6="OKOKOK",CQ6,0) -> 0 | CX6: TER A: TK/0 TK/1 K/0 | CY6: 5650001 | CZ6: s.d. | DA6: 5950000 | DB6: 0.005 | DC6: =IF(CX6=CY$2,"OK","") | DD6: =IF(CZ$2>=CY6,"OK","") -> OK | DE6: =IF(CZ$2<=DA6,"OK","") | DF6: =DC6&DD6&DE6 -> OK | DG6: =IF(DF6="OKOKOK",DB6,0) -> 0 | DI6: TER A: TK/0 TK/1 K/0 | DJ6: 5650001 | DK6: s.d. | DL6: 5950000 | DM6: 0.005 | DN6: =IF(DI6=DJ$2,"OK","") -> OK | DO6: =IF(DK$2>=DJ6,"OK","") -> OK | DP6: =IF(DK$2<=DL6,"OK","") | DQ6: =DN6&DO6&DP6 -> OKOK | DR6: =IF(DQ6="OKOKOK",DM6,0) -> 0
C7: PEGAWAI KE 4 | D7: TER A: TK/0 TK/1 K/0 | E7: =E6+5000000 -> 25000000 | F7: =SUMIFS($2:$2,$1:$1,C7) -> 0.1 | G7: =E7*F7 -> 2500000 | N7: TER A: TK/0 TK/1 K/0 | O7: 5950001 | P7: s.d. | Q7: 6300000 | R7: 0.0075 | S7: =IF(N7=O$2,"OK","") -> OK | T7: =IF(P$2>=O7,"OK","") -> OK | U7: =IF(P$2<=Q7,"OK","") | V7: =S7&T7&U7 -> OKOK | W7: =IF(V7="OKOKOK",R7,0) -> 0 | Y7: TER A: TK/0 TK/1 K/0 | Z7: 5950001 | AA7: s.d. | AB7: 6300000 | AC7: 0.0075 | AD7: =IF(Y7=Z$2,"OK","") | AE7: =IF(AA$2>=Z7,"OK","") -> OK | AF7: =IF(AA$2<=AB7,"OK","") | AG7: =AD7&AE7&AF7 -> OK | AH7: =IF(AG7="OKOKOK",AC7,0) -> 0 | AJ7: TER A: TK/0 TK/1 K/0 | AK7: 5950001 | AL7: s.d. | AM7: 6300000 | AN7: 0.0075 | AO7: =IF(AJ7=AK$2,"OK","") | AP7: =IF(AL$2>=AK7,"OK","") -> OK | AQ7: =IF(AL$2<=AM7,"OK","") | AR7: =AO7&AP7&AQ7 -> OK | AS7: =IF(AR7="OKOKOK",AN7,0) -> 0 | AU7: TER A: TK/0 TK/1 K/0 | AV7: 5950001 | AW7: s.d. | AX7: 6300000 | AY7: 0.0075 | AZ7: =IF(AU7=AV$2,"OK","") -> OK | BA7: =IF(AW$2>=AV7,"OK","") -> OK | BB7: =IF(AW$2<=AX7,"OK","") | BC7: =AZ7&BA7&BB7 -> OKOK | BD7: =IF(BC7="OKOKOK",AY7,0) -> 0 | BF7: TER A: TK/0 TK/1 K/0 | BG7: 5950001 | BH7: s.d. | BI7: 6300000 | BJ7: 0.0075 | BK7: =IF(BF7=BG$2,"OK","") | BL7: =IF(BH$2>=BG7,"OK","") -> OK | BM7: =IF(BH$2<=BI7,"OK","") | BN7: =BK7&BL7&BM7 -> OK | BO7: =IF(BN7="OKOKOK",BJ7,0) -> 0 | BQ7: TER A: TK/0 TK/1 K/0 | BR7: 5950001 | BS7: s.d. | BT7: 6300000 | BU7: 0.0075 | BV7: =IF(BQ7=BR$2,"OK","") | BW7: =IF(BS$2>=BR7,"OK","") -> OK | BX7: =IF(BS$2<=BT7,"OK","") | BY7: =BV7&BW7&BX7 -> OK | BZ7: =IF(BY7="OKOKOK",BU7,0) -> 0 | CB7: TER A: TK/0 TK/1 K/0 | CC7: 5950001 | CD7: s.d. | CE7: 6300000 | CF7: 0.0075 | CG7: =IF(CB7=CC$2,"OK","") -> OK | CH7: =IF(CD$2>=CC7,"OK","") -> OK | CI7: =IF(CD$2<=CE7,"OK","") | CJ7: =CG7&CH7&CI7 -> OKOK | CK7: =IF(CJ7="OKOKOK",CF7,0) -> 0 | CM7: TER A: TK/0 TK/1 K/0 | CN7: 5950001 | CO7: s.d. | CP7: 6300000 | CQ7: 0.0075 | CR7: =IF(CM7=CN$2,"OK","") | CS7: =IF(CO$2>=CN7,"OK","") -> OK | CT7: =IF(CO$2<=CP7,"OK","") | CU7: =CR7&CS7&CT7 -> OK | CV7: =IF(CU7="OKOKOK",CQ7,0) -> 0 | CX7: TER A: TK/0 TK/1 K/0 | CY7: 5950001 | CZ7: s.d. | DA7: 6300000 | DB7: 0.0075 | DC7: =IF(CX7=CY$2,"OK","") | DD7: =IF(CZ$2>=CY7,"OK","") -> OK | DE7: =IF(CZ$2<=DA7,"OK","") | DF7: =DC7&DD7&DE7 -> OK | DG7: =IF(DF7="OKOKOK",DB7,0) -> 0 | DI7: TER A: TK/0 TK/1 K/0 | DJ7: 5950001 | DK7: s.d. | DL7: 6300000 | DM7: 0.0075 | DN7: =IF(DI7=DJ$2,"OK","") -> OK | DO7: =IF(DK$2>=DJ7,"OK","") -> OK | DP7: =IF(DK$2<=DL7,"OK","") | DQ7: =DN7&DO7&DP7 -> OKOK | DR7: =IF(DQ7="OKOKOK",DM7,0) -> 0
C8: PEGAWAI KE 5 | D8: TER B: TK/2 TK/3 K/1 K/2 | E8: =E7+5000000 -> 30000000 | F8: =SUMIFS($2:$2,$1:$1,C8) -> 0.12 | G8: =E8*F8 -> 3600000 | N8: TER A: TK/0 TK/1 K/0 | O8: 6300001 | P8: s.d. | Q8: 6750000 | R8: 0.01 | S8: =IF(N8=O$2,"OK","") -> OK | T8: =IF(P$2>=O8,"OK","") -> OK | U8: =IF(P$2<=Q8,"OK","") | V8: =S8&T8&U8 -> OKOK | W8: =IF(V8="OKOKOK",R8,0) -> 0 | Y8: TER A: TK/0 TK/1 K/0 | Z8: 6300001 | AA8: s.d. | AB8: 6750000 | AC8: 0.01 | AD8: =IF(Y8=Z$2,"OK","") | AE8: =IF(AA$2>=Z8,"OK","") -> OK | AF8: =IF(AA$2<=AB8,"OK","") | AG8: =AD8&AE8&AF8 -> OK | AH8: =IF(AG8="OKOKOK",AC8,0) -> 0 | AJ8: TER A: TK/0 TK/1 K/0 | AK8: 6300001 | AL8: s.d. | AM8: 6750000 | AN8: 0.01 | AO8: =IF(AJ8=AK$2,"OK","") | AP8: =IF(AL$2>=AK8,"OK","") -> OK | AQ8: =IF(AL$2<=AM8,"OK","") | AR8: =AO8&AP8&AQ8 -> OK | AS8: =IF(AR8="OKOKOK",AN8,0) -> 0 | AU8: TER A: TK/0 TK/1 K/0 | AV8: 6300001 | AW8: s.d. | AX8: 6750000 | AY8: 0.01 | AZ8: =IF(AU8=AV$2,"OK","") -> OK | BA8: =IF(AW$2>=AV8,"OK","") -> OK | BB8: =IF(AW$2<=AX8,"OK","") | BC8: =AZ8&BA8&BB8 -> OKOK | BD8: =IF(BC8="OKOKOK",AY8,0) -> 0 | BF8: TER A: TK/0 TK/1 K/0 | BG8: 6300001 | BH8: s.d. | BI8: 6750000 | BJ8: 0.01 | BK8: =IF(BF8=BG$2,"OK","") | BL8: =IF(BH$2>=BG8,"OK","") -> OK | BM8: =IF(BH$2<=BI8,"OK","") | BN8: =BK8&BL8&BM8 -> OK | BO8: =IF(BN8="OKOKOK",BJ8,0) -> 0 | BQ8: TER A: TK/0 TK/1 K/0 | BR8: 6300001 | BS8: s.d. | BT8: 6750000 | BU8: 0.01 | BV8: =IF(BQ8=BR$2,"OK","") | BW8: =IF(BS$2>=BR8,"OK","") -> OK | BX8: =IF(BS$2<=BT8,"OK","") | BY8: =BV8&BW8&BX8 -> OK | BZ8: =IF(BY8="OKOKOK",BU8,0) -> 0 | CB8: TER A: TK/0 TK/1 K/0 | CC8: 6300001 | CD8: s.d. | CE8: 6750000 | CF8: 0.01 | CG8: =IF(CB8=CC$2,"OK","") -> OK | CH8: =IF(CD$2>=CC8,"OK","") -> OK | CI8: =IF(CD$2<=CE8,"OK","") | CJ8: =CG8&CH8&CI8 -> OKOK | CK8: =IF(CJ8="OKOKOK",CF8,0) -> 0 | CM8: TER A: TK/0 TK/1 K/0 | CN8: 6300001 | CO8: s.d. | CP8: 6750000 | CQ8: 0.01 | CR8: =IF(CM8=CN$2,"OK","") | CS8: =IF(CO$2>=CN8,"OK","") -> OK | CT8: =IF(CO$2<=CP8,"OK","") | CU8: =CR8&CS8&CT8 -> OK | CV8: =IF(CU8="OKOKOK",CQ8,0) -> 0 | CX8: TER A: TK/0 TK/1 K/0 | CY8: 6300001 | CZ8: s.d. | DA8: 6750000 | DB8: 0.01 | DC8: =IF(CX8=CY$2,"OK","") | DD8: =IF(CZ$2>=CY8,"OK","") -> OK | DE8: =IF(CZ$2<=DA8,"OK","") | DF8: =DC8&DD8&DE8 -> OK | DG8: =IF(DF8="OKOKOK",DB8,0) -> 0 | DI8: TER A: TK/0 TK/1 K/0 | DJ8: 6300001 | DK8: s.d. | DL8: 6750000 | DM8: 0.01 | DN8: =IF(DI8=DJ$2,"OK","") -> OK | DO8: =IF(DK$2>=DJ8,"OK","") -> OK | DP8: =IF(DK$2<=DL8,"OK","") | DQ8: =DN8&DO8&DP8 -> OKOK | DR8: =IF(DQ8="OKOKOK",DM8,0) -> 0
C9: PEGAWAI KE 6 | D9: TER C: K/3 | E9: =E8+5000000 -> 35000000 | F9: =SUMIFS($2:$2,$1:$1,C9) -> 0.14 | G9: =E9*F9 -> 4900000 | N9: TER A: TK/0 TK/1 K/0 | O9: 6750001 | P9: s.d. | Q9: 7500000 | R9: 0.0125 | S9: =IF(N9=O$2,"OK","") -> OK | T9: =IF(P$2>=O9,"OK","") -> OK | U9: =IF(P$2<=Q9,"OK","") | V9: =S9&T9&U9 -> OKOK | W9: =IF(V9="OKOKOK",R9,0) -> 0 | Y9: TER A: TK/0 TK/1 K/0 | Z9: 6750001 | AA9: s.d. | AB9: 7500000 | AC9: 0.0125 | AD9: =IF(Y9=Z$2,"OK","") | AE9: =IF(AA$2>=Z9,"OK","") -> OK | AF9: =IF(AA$2<=AB9,"OK","") | AG9: =AD9&AE9&AF9 -> OK | AH9: =IF(AG9="OKOKOK",AC9,0) -> 0 | AJ9: TER A: TK/0 TK/1 K/0 | AK9: 6750001 | AL9: s.d. | AM9: 7500000 | AN9: 0.0125 | AO9: =IF(AJ9=AK$2,"OK","") | AP9: =IF(AL$2>=AK9,"OK","") -> OK | AQ9: =IF(AL$2<=AM9,"OK","") | AR9: =AO9&AP9&AQ9 -> OK | AS9: =IF(AR9="OKOKOK",AN9,0) -> 0 | AU9: TER A: TK/0 TK/1 K/0 | AV9: 6750001 | AW9: s.d. | AX9: 7500000 | AY9: 0.0125 | AZ9: =IF(AU9=AV$2,"OK","") -> OK | BA9: =IF(AW$2>=AV9,"OK","") -> OK | BB9: =IF(AW$2<=AX9,"OK","") | BC9: =AZ9&BA9&BB9 -> OKOK | BD9: =IF(BC9="OKOKOK",AY9,0) -> 0 | BF9: TER A: TK/0 TK/1 K/0 | BG9: 6750001 | BH9: s.d. | BI9: 7500000 | BJ9: 0.0125 | BK9: =IF(BF9=BG$2,"OK","") | BL9: =IF(BH$2>=BG9,"OK","") -> OK | BM9: =IF(BH$2<=BI9,"OK","") | BN9: =BK9&BL9&BM9 -> OK | BO9: =IF(BN9="OKOKOK",BJ9,0) -> 0 | BQ9: TER A: TK/0 TK/1 K/0 | BR9: 6750001 | BS9: s.d. | BT9: 7500000 | BU9: 0.0125 | BV9: =IF(BQ9=BR$2,"OK","") | BW9: =IF(BS$2>=BR9,"OK","") -> OK | BX9: =IF(BS$2<=BT9,"OK","") | BY9: =BV9&BW9&BX9 -> OK | BZ9: =IF(BY9="OKOKOK",BU9,0) -> 0 | CB9: TER A: TK/0 TK/1 K/0 | CC9: 6750001 | CD9: s.d. | CE9: 7500000 | CF9: 0.0125 | CG9: =IF(CB9=CC$2,"OK","") -> OK | CH9: =IF(CD$2>=CC9,"OK","") -> OK | CI9: =IF(CD$2<=CE9,"OK","") | CJ9: =CG9&CH9&CI9 -> OKOK | CK9: =IF(CJ9="OKOKOK",CF9,0) -> 0 | CM9: TER A: TK/0 TK/1 K/0 | CN9: 6750001 | CO9: s.d. | CP9: 7500000 | CQ9: 0.0125 | CR9: =IF(CM9=CN$2,"OK","") | CS9: =IF(CO$2>=CN9,"OK","") -> OK | CT9: =IF(CO$2<=CP9,"OK","") | CU9: =CR9&CS9&CT9 -> OK | CV9: =IF(CU9="OKOKOK",CQ9,0) -> 0 | CX9: TER A: TK/0 TK/1 K/0 | CY9: 6750001 | CZ9: s.d. | DA9: 7500000 | DB9: 0.0125 | DC9: =IF(CX9=CY$2,"OK","") | DD9: =IF(CZ$2>=CY9,"OK","") -> OK | DE9: =IF(CZ$2<=DA9,"OK","") | DF9: =DC9&DD9&DE9 -> OK | DG9: =IF(DF9="OKOKOK",DB9,0) -> 0 | DI9: TER A: TK/0 TK/1 K/0 | DJ9: 6750001 | DK9: s.d. | DL9: 7500000 | DM9: 0.0125 | DN9: =IF(DI9=DJ$2,"OK","") -> OK | DO9: =IF(DK$2>=DJ9,"OK","") -> OK | DP9: =IF(DK$2<=DL9,"OK","") | DQ9: =DN9&DO9&DP9 -> OKOK | DR9: =IF(DQ9="OKOKOK",DM9,0) -> 0
C10: PEGAWAI KE 7 | D10: TER A: TK/0 TK/1 K/0 | E10: =E9+5000000 -> 40000000 | F10: =SUMIFS($2:$2,$1:$1,C10) -> 0.16 | G10: =E10*F10 -> 6400000 | N10: TER A: TK/0 TK/1 K/0 | O10: 7500001 | P10: s.d. | Q10: 8550000 | R10: 0.015 | S10: =IF(N10=O$2,"OK","") -> OK | T10: =IF(P$2>=O10,"OK","") -> OK | U10: =IF(P$2<=Q10,"OK","") | V10: =S10&T10&U10 -> OKOK | W10: =IF(V10="OKOKOK",R10,0) -> 0 | Y10: TER A: TK/0 TK/1 K/0 | Z10: 7500001 | AA10: s.d. | AB10: 8550000 | AC10: 0.015 | AD10: =IF(Y10=Z$2,"OK","") | AE10: =IF(AA$2>=Z10,"OK","") -> OK | AF10: =IF(AA$2<=AB10,"OK","") | AG10: =AD10&AE10&AF10 -> OK | AH10: =IF(AG10="OKOKOK",AC10,0) -> 0 | AJ10: TER A: TK/0 TK/1 K/0 | AK10: 7500001 | AL10: s.d. | AM10: 8550000 | AN10: 0.015 | AO10: =IF(AJ10=AK$2,"OK","") | AP10: =IF(AL$2>=AK10,"OK","") -> OK | AQ10: =IF(AL$2<=AM10,"OK","") | AR10: =AO10&AP10&AQ10 -> OK | AS10: =IF(AR10="OKOKOK",AN10,0) -> 0 | AU10: TER A: TK/0 TK/1 K/0 | AV10: 7500001 | AW10: s.d. | AX10: 8550000 | AY10: 0.015 | AZ10: =IF(AU10=AV$2,"OK","") -> OK | BA10: =IF(AW$2>=AV10,"OK","") -> OK | BB10: =IF(AW$2<=AX10,"OK","") | BC10: =AZ10&BA10&BB10 -> OKOK | BD10: =IF(BC10="OKOKOK",AY10,0) -> 0 | BF10: TER A: TK/0 TK/1 K/0 | BG10: 7500001 | BH10: s.d. | BI10: 8550000 | BJ10: 0.015 | BK10: =IF(BF10=BG$2,"OK","") | BL10: =IF(BH$2>=BG10,"OK","") -> OK | BM10: =IF(BH$2<=BI10,"OK","") | BN10: =BK10&BL10&BM10 -> OK | BO10: =IF(BN10="OKOKOK",BJ10,0) -> 0 | BQ10: TER A: TK/0 TK/1 K/0 | BR10: 7500001 | BS10: s.d. | BT10: 8550000 | BU10: 0.015 | BV10: =IF(BQ10=BR$2,"OK","") | BW10: =IF(BS$2>=BR10,"OK","") -> OK | BX10: =IF(BS$2<=BT10,"OK","") | BY10: =BV10&BW10&BX10 -> OK | BZ10: =IF(BY10="OKOKOK",BU10,0) -> 0 | CB10: TER A: TK/0 TK/1 K/0 | CC10: 7500001 | CD10: s.d. | CE10: 8550000 | CF10: 0.015 | CG10: =IF(CB10=CC$2,"OK","") -> OK | CH10: =IF(CD$2>=CC10,"OK","") -> OK | CI10: =IF(CD$2<=CE10,"OK","") | CJ10: =CG10&CH10&CI10 -> OKOK | CK10: =IF(CJ10="OKOKOK",CF10,0) -> 0 | CM10: TER A: TK/0 TK/1 K/0 | CN10: 7500001 | CO10: s.d. | CP10: 8550000 | CQ10: 0.015 | CR10: =IF(CM10=CN$2,"OK","") | CS10: =IF(CO$2>=CN10,"OK","") -> OK | CT10: =IF(CO$2<=CP10,"OK","") | CU10: =CR10&CS10&CT10 -> OK | CV10: =IF(CU10="OKOKOK",CQ10,0) -> 0 | CX10: TER A: TK/0 TK/1 K/0 | CY10: 7500001 | CZ10: s.d. | DA10: 8550000 | DB10: 0.015 | DC10: =IF(CX10=CY$2,"OK","") | DD10: =IF(CZ$2>=CY10,"OK","") -> OK | DE10: =IF(CZ$2<=DA10,"OK","") | DF10: =DC10&DD10&DE10 -> OK | DG10: =IF(DF10="OKOKOK",DB10,0) -> 0 | DI10: TER A: TK/0 TK/1 K/0 | DJ10: 7500001 | DK10: s.d. | DL10: 8550000 | DM10: 0.015 | DN10: =IF(DI10=DJ$2,"OK","") -> OK | DO10: =IF(DK$2>=DJ10,"OK","") -> OK | DP10: =IF(DK$2<=DL10,"OK","") | DQ10: =DN10&DO10&DP10 -> OKOK | DR10: =IF(DQ10="OKOKOK",DM10,0) -> 0
C11: PEGAWAI KE 8 | D11: TER B: TK/2 TK/3 K/1 K/2 | E11: =E10+5000000 -> 45000000 | F11: =SUMIFS($2:$2,$1:$1,C11) -> 0.16 | G11: =E11*F11 -> 7200000 | N11: TER A: TK/0 TK/1 K/0 | O11: 8550001 | P11: s.d. | Q11: 9650000 | R11: 0.0175 | S11: =IF(N11=O$2,"OK","") -> OK | T11: =IF(P$2>=O11,"OK","") -> OK | U11: =IF(P$2<=Q11,"OK","") | V11: =S11&T11&U11 -> OKOK | W11: =IF(V11="OKOKOK",R11,0) -> 0 | Y11: TER A: TK/0 TK/1 K/0 | Z11: 8550001 | AA11: s.d. | AB11: 9650000 | AC11: 0.0175 | AD11: =IF(Y11=Z$2,"OK","") | AE11: =IF(AA$2>=Z11,"OK","") -> OK | AF11: =IF(AA$2<=AB11,"OK","") | AG11: =AD11&AE11&AF11 -> OK | AH11: =IF(AG11="OKOKOK",AC11,0) -> 0 | AJ11: TER A: TK/0 TK/1 K/0 | AK11: 8550001 | AL11: s.d. | AM11: 9650000 | AN11: 0.0175 | AO11: =IF(AJ11=AK$2,"OK","") | AP11: =IF(AL$2>=AK11,"OK","") -> OK | AQ11: =IF(AL$2<=AM11,"OK","") | AR11: =AO11&AP11&AQ11 -> OK | AS11: =IF(AR11="OKOKOK",AN11,0) -> 0 | AU11: TER A: TK/0 TK/1 K/0 | AV11: 8550001 | AW11: s.d. | AX11: 9650000 | AY11: 0.0175 | AZ11: =IF(AU11=AV$2,"OK","") -> OK | BA11: =IF(AW$2>=AV11,"OK","") -> OK | BB11: =IF(AW$2<=AX11,"OK","") | BC11: =AZ11&BA11&BB11 -> OKOK | BD11: =IF(BC11="OKOKOK",AY11,0) -> 0 | BF11: TER A: TK/0 TK/1 K/0 | BG11: 8550001 | BH11: s.d. | BI11: 9650000 | BJ11: 0.0175 | BK11: =IF(BF11=BG$2,"OK","") | BL11: =IF(BH$2>=BG11,"OK","") -> OK | BM11: =IF(BH$2<=BI11,"OK","") | BN11: =BK11&BL11&BM11 -> OK | BO11: =IF(BN11="OKOKOK",BJ11,0) -> 0 | BQ11: TER A: TK/0 TK/1 K/0 | BR11: 8550001 | BS11: s.d. | BT11: 9650000 | BU11: 0.0175 | BV11: =IF(BQ11=BR$2,"OK","") | BW11: =IF(BS$2>=BR11,"OK","") -> OK | BX11: =IF(BS$2<=BT11,"OK","") | BY11: =BV11&BW11&BX11 -> OK | BZ11: =IF(BY11="OKOKOK",BU11,0) -> 0 | CB11: TER A: TK/0 TK/1 K/0 | CC11: 8550001 | CD11: s.d. | CE11: 9650000 | CF11: 0.0175 | CG11: =IF(CB11=CC$2,"OK","") -> OK | CH11: =IF(CD$2>=CC11,"OK","") -> OK | CI11: =IF(CD$2<=CE11,"OK","") | CJ11: =CG11&CH11&CI11 -> OKOK | CK11: =IF(CJ11="OKOKOK",CF11,0) -> 0 | CM11: TER A: TK/0 TK/1 K/0 | CN11: 8550001 | CO11: s.d. | CP11: 9650000 | CQ11: 0.0175 | CR11: =IF(CM11=CN$2,"OK","") | CS11: =IF(CO$2>=CN11,"OK","") -> OK | CT11: =IF(CO$2<=CP11,"OK","") | CU11: =CR11&CS11&CT11 -> OK | CV11: =IF(CU11="OKOKOK",CQ11,0) -> 0 | CX11: TER A: TK/0 TK/1 K/0 | CY11: 8550001 | CZ11: s.d. | DA11: 9650000 | DB11: 0.0175 | DC11: =IF(CX11=CY$2,"OK","") | DD11: =IF(CZ$2>=CY11,"OK","") -> OK | DE11: =IF(CZ$2<=DA11,"OK","") | DF11: =DC11&DD11&DE11 -> OK | DG11: =IF(DF11="OKOKOK",DB11,0) -> 0 | DI11: TER A: TK/0 TK/1 K/0 | DJ11: 8550001 | DK11: s.d. | DL11: 9650000 | DM11: 0.0175 | DN11: =IF(DI11=DJ$2,"OK","") -> OK | DO11: =IF(DK$2>=DJ11,"OK","") -> OK | DP11: =IF(DK$2<=DL11,"OK","") | DQ11: =DN11&DO11&DP11 -> OKOK | DR11: =IF(DQ11="OKOKOK",DM11,0) -> 0
C12: PEGAWAI KE 9 | D12: TER C: K/3 | E12: =E11+5000000 -> 50000000 | F12: =SUMIFS($2:$2,$1:$1,C12) -> 0.18 | G12: =E12*F12 -> 9000000 | N12: TER A: TK/0 TK/1 K/0 | O12: 9650001 | P12: s.d. | Q12: 10050000 | R12: 0.02 | S12: =IF(N12=O$2,"OK","") -> OK | T12: =IF(P$2>=O12,"OK","") -> OK | U12: =IF(P$2<=Q12,"OK","") -> OK | V12: =S12&T12&U12 -> OKOKOK | W12: =IF(V12="OKOKOK",R12,0) -> 0.02 | Y12: TER A: TK/0 TK/1 K/0 | Z12: 9650001 | AA12: s.d. | AB12: 10050000 | AC12: 0.02 | AD12: =IF(Y12=Z$2,"OK","") | AE12: =IF(AA$2>=Z12,"OK","") -> OK | AF12: =IF(AA$2<=AB12,"OK","") | AG12: =AD12&AE12&AF12 -> OK | AH12: =IF(AG12="OKOKOK",AC12,0) -> 0 | AJ12: TER A: TK/0 TK/1 K/0 | AK12: 9650001 | AL12: s.d. | AM12: 10050000 | AN12: 0.02 | AO12: =IF(AJ12=AK$2,"OK","") | AP12: =IF(AL$2>=AK12,"OK","") -> OK | AQ12: =IF(AL$2<=AM12,"OK","") | AR12: =AO12&AP12&AQ12 -> OK | AS12: =IF(AR12="OKOKOK",AN12,0) -> 0 | AU12: TER A: TK/0 TK/1 K/0 | AV12: 9650001 | AW12: s.d. | AX12: 10050000 | AY12: 0.02 | AZ12: =IF(AU12=AV$2,"OK","") -> OK | BA12: =IF(AW$2>=AV12,"OK","") -> OK | BB12: =IF(AW$2<=AX12,"OK","") | BC12: =AZ12&BA12&BB12 -> OKOK | BD12: =IF(BC12="OKOKOK",AY12,0) -> 0 | BF12: TER A: TK/0 TK/1 K/0 | BG12: 9650001 | BH12: s.d. | BI12: 10050000 | BJ12: 0.02 | BK12: =IF(BF12=BG$2,"OK","") | BL12: =IF(BH$2>=BG12,"OK","") -> OK | BM12: =IF(BH$2<=BI12,"OK","") | BN12: =BK12&BL12&BM12 -> OK | BO12: =IF(BN12="OKOKOK",BJ12,0) -> 0 | BQ12: TER A: TK/0 TK/1 K/0 | BR12: 9650001 | BS12: s.d. | BT12: 10050000 | BU12: 0.02 | BV12: =IF(BQ12=BR$2,"OK","") | BW12: =IF(BS$2>=BR12,"OK","") -> OK | BX12: =IF(BS$2<=BT12,"OK","") | BY12: =BV12&BW12&BX12 -> OK | BZ12: =IF(BY12="OKOKOK",BU12,0) -> 0 | CB12: TER A: TK/0 TK/1 K/0 | CC12: 9650001 | CD12: s.d. | CE12: 10050000 | CF12: 0.02 | CG12: =IF(CB12=CC$2,"OK","") -> OK | CH12: =IF(CD$2>=CC12,"OK","") -> OK | CI12: =IF(CD$2<=CE12,"OK","") | CJ12: =CG12&CH12&CI12 -> OKOK | CK12: =IF(CJ12="OKOKOK",CF12,0) -> 0 | CM12: TER A: TK/0 TK/1 K/0 | CN12: 9650001 | CO12: s.d. | CP12: 10050000 | CQ12: 0.02 | CR12: =IF(CM12=CN$2,"OK","") | CS12: =IF(CO$2>=CN12,"OK","") -> OK | CT12: =IF(CO$2<=CP12,"OK","") | CU12: =CR12&CS12&CT12 -> OK | CV12: =IF(CU12="OKOKOK",CQ12,0) -> 0 | CX12: TER A: TK/0 TK/1 K/0 | CY12: 9650001 | CZ12: s.d. | DA12: 10050000 | DB12: 0.02 | DC12: =IF(CX12=CY$2,"OK","") | DD12: =IF(CZ$2>=CY12,"OK","") -> OK | DE12: =IF(CZ$2<=DA12,"OK","") | DF12: =DC12&DD12&DE12 -> OK | DG12: =IF(DF12="OKOKOK",DB12,0) -> 0 | DI12: TER A: TK/0 TK/1 K/0 | DJ12: 9650001 | DK12: s.d. | DL12: 10050000 | DM12: 0.02 | DN12: =IF(DI12=DJ$2,"OK","") -> OK | DO12: =IF(DK$2>=DJ12,"OK","") -> OK | DP12: =IF(DK$2<=DL12,"OK","") | DQ12: =DN12&DO12&DP12 -> OKOK | DR12: =IF(DQ12="OKOKOK",DM12,0) -> 0
C13: PEGAWAI KE 10 | D13: TER A: TK/0 TK/1 K/0 | E13: =E12+5000000 -> 55000000 | F13: =SUMIFS($2:$2,$1:$1,C13) -> 0.19 | G13: =E13*F13 -> 10450000 | N13: TER A: TK/0 TK/1 K/0 | O13: 10050001 | P13: s.d. | Q13: 10350000 | R13: 0.0225 | S13: =IF(N13=O$2,"OK","") -> OK | T13: =IF(P$2>=O13,"OK","") | U13: =IF(P$2<=Q13,"OK","") -> OK | V13: =S13&T13&U13 -> OKOK | W13: =IF(V13="OKOKOK",R13,0) -> 0 | Y13: TER A: TK/0 TK/1 K/0 | Z13: 10050001 | AA13: s.d. | AB13: 10350000 | AC13: 0.0225 | AD13: =IF(Y13=Z$2,"OK","") | AE13: =IF(AA$2>=Z13,"OK","") -> OK | AF13: =IF(AA$2<=AB13,"OK","") | AG13: =AD13&AE13&AF13 -> OK | AH13: =IF(AG13="OKOKOK",AC13,0) -> 0 | AJ13: TER A: TK/0 TK/1 K/0 | AK13: 10050001 | AL13: s.d. | AM13: 10350000 | AN13: 0.0225 | AO13: =IF(AJ13=AK$2,"OK","") | AP13: =IF(AL$2>=AK13,"OK","") -> OK | AQ13: =IF(AL$2<=AM13,"OK","") | AR13: =AO13&AP13&AQ13 -> OK | AS13: =IF(AR13="OKOKOK",AN13,0) -> 0 | AU13: TER A: TK/0 TK/1 K/0 | AV13: 10050001 | AW13: s.d. | AX13: 10350000 | AY13: 0.0225 | AZ13: =IF(AU13=AV$2,"OK","") -> OK | BA13: =IF(AW$2>=AV13,"OK","") -> OK | BB13: =IF(AW$2<=AX13,"OK","") | BC13: =AZ13&BA13&BB13 -> OKOK | BD13: =IF(BC13="OKOKOK",AY13,0) -> 0 | BF13: TER A: TK/0 TK/1 K/0 | BG13: 10050001 | BH13: s.d. | BI13: 10350000 | BJ13: 0.0225 | BK13: =IF(BF13=BG$2,"OK","") | BL13: =IF(BH$2>=BG13,"OK","") -> OK | BM13: =IF(BH$2<=BI13,"OK","") | BN13: =BK13&BL13&BM13 -> OK | BO13: =IF(BN13="OKOKOK",BJ13,0) -> 0 | BQ13: TER A: TK/0 TK/1 K/0 | BR13: 10050001 | BS13: s.d. | BT13: 10350000 | BU13: 0.0225 | BV13: =IF(BQ13=BR$2,"OK","") | BW13: =IF(BS$2>=BR13,"OK","") -> OK | BX13: =IF(BS$2<=BT13,"OK","") | BY13: =BV13&BW13&BX13 -> OK | BZ13: =IF(BY13="OKOKOK",BU13,0) -> 0 | CB13: TER A: TK/0 TK/1 K/0 | CC13: 10050001 | CD13: s.d. | CE13: 10350000 | CF13: 0.0225 | CG13: =IF(CB13=CC$2,"OK","") -> OK | CH13: =IF(CD$2>=CC13,"OK","") -> OK | CI13: =IF(CD$2<=CE13,"OK","") | CJ13: =CG13&CH13&CI13 -> OKOK | CK13: =IF(CJ13="OKOKOK",CF13,0) -> 0 | CM13: TER A: TK/0 TK/1 K/0 | CN13: 10050001 | CO13: s.d. | CP13: 10350000 | CQ13: 0.0225 | CR13: =IF(CM13=CN$2,"OK","") | CS13: =IF(CO$2>=CN13,"OK","") -> OK | CT13: =IF(CO$2<=CP13,"OK","") | CU13: =CR13&CS13&CT13 -> OK | CV13: =IF(CU13="OKOKOK",CQ13,0) -> 0 | CX13: TER A: TK/0 TK/1 K/0 | CY13: 10050001 | CZ13: s.d. | DA13: 10350000 | DB13: 0.0225 | DC13: =IF(CX13=CY$2,"OK","") | DD13: =IF(CZ$2>=CY13,"OK","") -> OK | DE13: =IF(CZ$2<=DA13,"OK","") | DF13: =DC13&DD13&DE13 -> OK | DG13: =IF(DF13="OKOKOK",DB13,0) -> 0 | DI13: TER A: TK/0 TK/1 K/0 | DJ13: 10050001 | DK13: s.d. | DL13: 10350000 | DM13: 0.0225 | DN13: =IF(DI13=DJ$2,"OK","") -> OK | DO13: =IF(DK$2>=DJ13,"OK","") -> OK | DP13: =IF(DK$2<=DL13,"OK","") | DQ13: =DN13&DO13&DP13 -> OKOK | DR13: =IF(DQ13="OKOKOK",DM13,0) -> 0
D14: JUMLAH | G14: =SUM(G4:G13) -> 46750000 | N14: TER A: TK/0 TK/1 K/0 | O14: 10350001 | P14: s.d. | Q14: 10700000 | R14: 0.025 | S14: =IF(N14=O$2,"OK","") -> OK | T14: =IF(P$2>=O14,"OK","") | U14: =IF(P$2<=Q14,"OK","") -> OK | V14: =S14&T14&U14 -> OKOK | W14: =IF(V14="OKOKOK",R14,0) -> 0 | Y14: TER A: TK/0 TK/1 K/0 | Z14: 10350001 | AA14: s.d. | AB14: 10700000 | AC14: 0.025 | AD14: =IF(Y14=Z$2,"OK","") | AE14: =IF(AA$2>=Z14,"OK","") -> OK | AF14: =IF(AA$2<=AB14,"OK","") | AG14: =AD14&AE14&AF14 -> OK | AH14: =IF(AG14="OKOKOK",AC14,0) -> 0 | AJ14: TER A: TK/0 TK/1 K/0 | AK14: 10350001 | AL14: s.d. | AM14: 10700000 | AN14: 0.025 | AO14: =IF(AJ14=AK$2,"OK","") | AP14: =IF(AL$2>=AK14,"OK","") -> OK | AQ14: =IF(AL$2<=AM14,"OK","") | AR14: =AO14&AP14&AQ14 -> OK | AS14: =IF(AR14="OKOKOK",AN14,0) -> 0 | AU14: TER A: TK/0 TK/1 K/0 | AV14: 10350001 | AW14: s.d. | AX14: 10700000 | AY14: 0.025 | AZ14: =IF(AU14=AV$2,"OK","") -> OK | BA14: =IF(AW$2>=AV14,"OK","") -> OK | BB14: =IF(AW$2<=AX14,"OK","") | BC14: =AZ14&BA14&BB14 -> OKOK | BD14: =IF(BC14="OKOKOK",AY14,0) -> 0 | BF14: TER A: TK/0 TK/1 K/0 | BG14: 10350001 | BH14: s.d. | BI14: 10700000 | BJ14: 0.025 | BK14: =IF(BF14=BG$2,"OK","") | BL14: =IF(BH$2>=BG14,"OK","") -> OK | BM14: =IF(BH$2<=BI14,"OK","") | BN14: =BK14&BL14&BM14 -> OK | BO14: =IF(BN14="OKOKOK",BJ14,0) -> 0 | BQ14: TER A: TK/0 TK/1 K/0 | BR14: 10350001 | BS14: s.d. | BT14: 10700000 | BU14: 0.025 | BV14: =IF(BQ14=BR$2,"OK","") | BW14: =IF(BS$2>=BR14,"OK","") -> OK | BX14: =IF(BS$2<=BT14,"OK","") | BY14: =BV14&BW14&BX14 -> OK | BZ14: =IF(BY14="OKOKOK",BU14,0) -> 0 | CB14: TER A: TK/0 TK/1 K/0 | CC14: 10350001 | CD14: s.d. | CE14: 10700000 | CF14: 0.025 | CG14: =IF(CB14=CC$2,"OK","") -> OK | CH14: =IF(CD$2>=CC14,"OK","") -> OK | CI14: =IF(CD$2<=CE14,"OK","") | CJ14: =CG14&CH14&CI14 -> OKOK | CK14: =IF(CJ14="OKOKOK",CF14,0) -> 0 | CM14: TER A: TK/0 TK/1 K/0 | CN14: 10350001 | CO14: s.d. | CP14: 10700000 | CQ14: 0.025 | CR14: =IF(CM14=CN$2,"OK","") | CS14: =IF(CO$2>=CN14,"OK","") -> OK | CT14: =IF(CO$2<=CP14,"OK","") | CU14: =CR14&CS14&CT14 -> OK | CV14: =IF(CU14="OKOKOK",CQ14,0) -> 0 | CX14: TER A: TK/0 TK/1 K/0 | CY14: 10350001 | CZ14: s.d. | DA14: 10700000 | DB14: 0.025 | DC14: =IF(CX14=CY$2,"OK","") | DD14: =IF(CZ$2>=CY14,"OK","") -> OK | DE14: =IF(CZ$2<=DA14,"OK","") | DF14: =DC14&DD14&DE14 -> OK | DG14: =IF(DF14="OKOKOK",DB14,0) -> 0 | DI14: TER A: TK/0 TK/1 K/0 | DJ14: 10350001 | DK14: s.d. | DL14: 10700000 | DM14: 0.025 | DN14: =IF(DI14=DJ$2,"OK","") -> OK | DO14: =IF(DK$2>=DJ14,"OK","") -> OK | DP14: =IF(DK$2<=DL14,"OK","") | DQ14: =DN14&DO14&DP14 -> OKOK | DR14: =IF(DQ14="OKOKOK",DM14,0) -> 0
N15: TER A: TK/0 TK/1 K/0 | O15: 10700001 | P15: s.d. | Q15: 11050000 | R15: 0.03 | S15: =IF(N15=O$2,"OK","") -> OK | T15: =IF(P$2>=O15,"OK","") | U15: =IF(P$2<=Q15,"OK","") -> OK | V15: =S15&T15&U15 -> OKOK | W15: =IF(V15="OKOKOK",R15,0) -> 0 | Y15: TER A: TK/0 TK/1 K/0 | Z15: 10700001 | AA15: s.d. | AB15: 11050000 | AC15: 0.03 | AD15: =IF(Y15=Z$2,"OK","") | AE15: =IF(AA$2>=Z15,"OK","") -> OK | AF15: =IF(AA$2<=AB15,"OK","") | AG15: =AD15&AE15&AF15 -> OK | AH15: =IF(AG15="OKOKOK",AC15,0) -> 0 | AJ15: TER A: TK/0 TK/1 K/0 | AK15: 10700001 | AL15: s.d. | AM15: 11050000 | AN15: 0.03 | AO15: =IF(AJ15=AK$2,"OK","") | AP15: =IF(AL$2>=AK15,"OK","") -> OK | AQ15: =IF(AL$2<=AM15,"OK","") | AR15: =AO15&AP15&AQ15 -> OK | AS15: =IF(AR15="OKOKOK",AN15,0) -> 0 | AU15: TER A: TK/0 TK/1 K/0 | AV15: 10700001 | AW15: s.d. | AX15: 11050000 | AY15: 0.03 | AZ15: =IF(AU15=AV$2,"OK","") -> OK | BA15: =IF(AW$2>=AV15,"OK","") -> OK | BB15: =IF(AW$2<=AX15,"OK","") | BC15: =AZ15&BA15&BB15 -> OKOK | BD15: =IF(BC15="OKOKOK",AY15,0) -> 0 | BF15: TER A: TK/0 TK/1 K/0 | BG15: 10700001 | BH15: s.d. | BI15: 11050000 | BJ15: 0.03 | BK15: =IF(BF15=BG$2,"OK","") | BL15: =IF(BH$2>=BG15,"OK","") -> OK | BM15: =IF(BH$2<=BI15,"OK","") | BN15: =BK15&BL15&BM15 -> OK | BO15: =IF(BN15="OKOKOK",BJ15,0) -> 0 | BQ15: TER A: TK/0 TK/1 K/0 | BR15: 10700001 | BS15: s.d. | BT15: 11050000 | BU15: 0.03 | BV15: =IF(BQ15=BR$2,"OK","") | BW15: =IF(BS$2>=BR15,"OK","") -> OK | BX15: =IF(BS$2<=BT15,"OK","") | BY15: =BV15&BW15&BX15 -> OK | BZ15: =IF(BY15="OKOKOK",BU15,0) -> 0 | CB15: TER A: TK/0 TK/1 K/0 | CC15: 10700001 | CD15: s.d. | CE15: 11050000 | CF15: 0.03 | CG15: =IF(CB15=CC$2,"OK","") -> OK | CH15: =IF(CD$2>=CC15,"OK","") -> OK | CI15: =IF(CD$2<=CE15,"OK","") | CJ15: =CG15&CH15&CI15 -> OKOK | CK15: =IF(CJ15="OKOKOK",CF15,0) -> 0 | CM15: TER A: TK/0 TK/1 K/0 | CN15: 10700001 | CO15: s.d. | CP15: 11050000 | CQ15: 0.03 | CR15: =IF(CM15=CN$2,"OK","") | CS15: =IF(CO$2>=CN15,"OK","") -> OK | CT15: =IF(CO$2<=CP15,"OK","") | CU15: =CR15&CS15&CT15 -> OK | CV15: =IF(CU15="OKOKOK",CQ15,0) -> 0 | CX15: TER A: TK/0 TK/1 K/0 | CY15: 10700001 | CZ15: s.d. | DA15: 11050000 | DB15: 0.03 | DC15: =IF(CX15=CY$2,"OK","") | DD15: =IF(CZ$2>=CY15,"OK","") -> OK | DE15: =IF(CZ$2<=DA15,"OK","") | DF15: =DC15&DD15&DE15 -> OK | DG15: =IF(DF15="OKOKOK",DB15,0) -> 0 | DI15: TER A: TK/0 TK/1 K/0 | DJ15: 10700001 | DK15: s.d. | DL15: 11050000 | DM15: 0.03 | DN15: =IF(DI15=DJ$2,"OK","") -> OK | DO15: =IF(DK$2>=DJ15,"OK","") -> OK | DP15: =IF(DK$2<=DL15,"OK","") | DQ15: =DN15&DO15&DP15 -> OKOK | DR15: =IF(DQ15="OKOKOK",DM15,0) -> 0
C16: TIDAK SEMUA PENGHASILAN PPH 21 DIKENAKAN TARIF **TER** | N16: TER A: TK/0 TK/1 K/0 | O16: 11050001 | P16: s.d. | Q16: 11600000 | R16: 0.035 | S16: =IF(N16=O$2,"OK","") -> OK | T16: =IF(P$2>=O16,"OK","") | U16: =IF(P$2<=Q16,"OK","") -> OK | V16: =S16&T16&U16 -> OKOK | W16: =IF(V16="OKOKOK",R16,0) -> 0 | Y16: TER A: TK/0 TK/1 K/0 | Z16: 11050001 | AA16: s.d. | AB16: 11600000 | AC16: 0.035 | AD16: =IF(Y16=Z$2,"OK","") | AE16: =IF(AA$2>=Z16,"OK","") -> OK | AF16: =IF(AA$2<=AB16,"OK","") | AG16: =AD16&AE16&AF16 -> OK | AH16: =IF(AG16="OKOKOK",AC16,0) -> 0 | AJ16: TER A: TK/0 TK/1 K/0 | AK16: 11050001 | AL16: s.d. | AM16: 11600000 | AN16: 0.035 | AO16: =IF(AJ16=AK$2,"OK","") | AP16: =IF(AL$2>=AK16,"OK","") -> OK | AQ16: =IF(AL$2<=AM16,"OK","") | AR16: =AO16&AP16&AQ16 -> OK | AS16: =IF(AR16="OKOKOK",AN16,0) -> 0 | AU16: TER A: TK/0 TK/1 K/0 | AV16: 11050001 | AW16: s.d. | AX16: 11600000 | AY16: 0.035 | AZ16: =IF(AU16=AV$2,"OK","") -> OK | BA16: =IF(AW$2>=AV16,"OK","") -> OK | BB16: =IF(AW$2<=AX16,"OK","") | BC16: =AZ16&BA16&BB16 -> OKOK | BD16: =IF(BC16="OKOKOK",AY16,0) -> 0 | BF16: TER A: TK/0 TK/1 K/0 | BG16: 11050001 | BH16: s.d. | BI16: 11600000 | BJ16: 0.035 | BK16: =IF(BF16=BG$2,"OK","") | BL16: =IF(BH$2>=BG16,"OK","") -> OK | BM16: =IF(BH$2<=BI16,"OK","") | BN16: =BK16&BL16&BM16 -> OK | BO16: =IF(BN16="OKOKOK",BJ16,0) -> 0 | BQ16: TER A: TK/0 TK/1 K/0 | BR16: 11050001 | BS16: s.d. | BT16: 11600000 | BU16: 0.035 | BV16: =IF(BQ16=BR$2,"OK","") | BW16: =IF(BS$2>=BR16,"OK","") -> OK | BX16: =IF(BS$2<=BT16,"OK","") | BY16: =BV16&BW16&BX16 -> OK | BZ16: =IF(BY16="OKOKOK",BU16,0) -> 0 | CB16: TER A: TK/0 TK/1 K/0 | CC16: 11050001 | CD16: s.d. | CE16: 11600000 | CF16: 0.035 | CG16: =IF(CB16=CC$2,"OK","") -> OK | CH16: =IF(CD$2>=CC16,"OK","") -> OK | CI16: =IF(CD$2<=CE16,"OK","") | CJ16: =CG16&CH16&CI16 -> OKOK | CK16: =IF(CJ16="OKOKOK",CF16,0) -> 0 | CM16: TER A: TK/0 TK/1 K/0 | CN16: 11050001 | CO16: s.d. | CP16: 11600000 | CQ16: 0.035 | CR16: =IF(CM16=CN$2,"OK","") | CS16: =IF(CO$2>=CN16,"OK","") -> OK | CT16: =IF(CO$2<=CP16,"OK","") | CU16: =CR16&CS16&CT16 -> OK | CV16: =IF(CU16="OKOKOK",CQ16,0) -> 0 | CX16: TER A: TK/0 TK/1 K/0 | CY16: 11050001 | CZ16: s.d. | DA16: 11600000 | DB16: 0.035 | DC16: =IF(CX16=CY$2,"OK","") | DD16: =IF(CZ$2>=CY16,"OK","") -> OK | DE16: =IF(CZ$2<=DA16,"OK","") | DF16: =DC16&DD16&DE16 -> OK | DG16: =IF(DF16="OKOKOK",DB16,0) -> 0 | DI16: TER A: TK/0 TK/1 K/0 | DJ16: 11050001 | DK16: s.d. | DL16: 11600000 | DM16: 0.035 | DN16: =IF(DI16=DJ$2,"OK","") -> OK | DO16: =IF(DK$2>=DJ16,"OK","") -> OK | DP16: =IF(DK$2<=DL16,"OK","") | DQ16: =DN16&DO16&DP16 -> OKOK | DR16: =IF(DQ16="OKOKOK",DM16,0) -> 0
C17: YANG MASUK KE **TER** PPh 21 YAKNI | N17: TER A: TK/0 TK/1 K/0 | O17: 11600001 | P17: s.d. | Q17: 12500000 | R17: 0.04 | S17: =IF(N17=O$2,"OK","") -> OK | T17: =IF(P$2>=O17,"OK","") | U17: =IF(P$2<=Q17,"OK","") -> OK | V17: =S17&T17&U17 -> OKOK | W17: =IF(V17="OKOKOK",R17,0) -> 0 | Y17: TER A: TK/0 TK/1 K/0 | Z17: 11600001 | AA17: s.d. | AB17: 12500000 | AC17: 0.04 | AD17: =IF(Y17=Z$2,"OK","") | AE17: =IF(AA$2>=Z17,"OK","") -> OK | AF17: =IF(AA$2<=AB17,"OK","") | AG17: =AD17&AE17&AF17 -> OK | AH17: =IF(AG17="OKOKOK",AC17,0) -> 0 | AJ17: TER A: TK/0 TK/1 K/0 | AK17: 11600001 | AL17: s.d. | AM17: 12500000 | AN17: 0.04 | AO17: =IF(AJ17=AK$2,"OK","") | AP17: =IF(AL$2>=AK17,"OK","") -> OK | AQ17: =IF(AL$2<=AM17,"OK","") | AR17: =AO17&AP17&AQ17 -> OK | AS17: =IF(AR17="OKOKOK",AN17,0) -> 0 | AU17: TER A: TK/0 TK/1 K/0 | AV17: 11600001 | AW17: s.d. | AX17: 12500000 | AY17: 0.04 | AZ17: =IF(AU17=AV$2,"OK","") -> OK | BA17: =IF(AW$2>=AV17,"OK","") -> OK | BB17: =IF(AW$2<=AX17,"OK","") | BC17: =AZ17&BA17&BB17 -> OKOK | BD17: =IF(BC17="OKOKOK",AY17,0) -> 0 | BF17: TER A: TK/0 TK/1 K/0 | BG17: 11600001 | BH17: s.d. | BI17: 12500000 | BJ17: 0.04 | BK17: =IF(BF17=BG$2,"OK","") | BL17: =IF(BH$2>=BG17,"OK","") -> OK | BM17: =IF(BH$2<=BI17,"OK","") | BN17: =BK17&BL17&BM17 -> OK | BO17: =IF(BN17="OKOKOK",BJ17,0) -> 0 | BQ17: TER A: TK/0 TK/1 K/0 | BR17: 11600001 | BS17: s.d. | BT17: 12500000 | BU17: 0.04 | BV17: =IF(BQ17=BR$2,"OK","") | BW17: =IF(BS$2>=BR17,"OK","") -> OK | BX17: =IF(BS$2<=BT17,"OK","") | BY17: =BV17&BW17&BX17 -> OK | BZ17: =IF(BY17="OKOKOK",BU17,0) -> 0 | CB17: TER A: TK/0 TK/1 K/0 | CC17: 11600001 | CD17: s.d. | CE17: 12500000 | CF17: 0.04 | CG17: =IF(CB17=CC$2,"OK","") -> OK | CH17: =IF(CD$2>=CC17,"OK","") -> OK | CI17: =IF(CD$2<=CE17,"OK","") | CJ17: =CG17&CH17&CI17 -> OKOK | CK17: =IF(CJ17="OKOKOK",CF17,0) -> 0 | CM17: TER A: TK/0 TK/1 K/0 | CN17: 11600001 | CO17: s.d. | CP17: 12500000 | CQ17: 0.04 | CR17: =IF(CM17=CN$2,"OK","") | CS17: =IF(CO$2>=CN17,"OK","") -> OK | CT17: =IF(CO$2<=CP17,"OK","") | CU17: =CR17&CS17&CT17 -> OK | CV17: =IF(CU17="OKOKOK",CQ17,0) -> 0 | CX17: TER A: TK/0 TK/1 K/0 | CY17: 11600001 | CZ17: s.d. | DA17: 12500000 | DB17: 0.04 | DC17: =IF(CX17=CY$2,"OK","") | DD17: =IF(CZ$2>=CY17,"OK","") -> OK | DE17: =IF(CZ$2<=DA17,"OK","") | DF17: =DC17&DD17&DE17 -> OK | DG17: =IF(DF17="OKOKOK",DB17,0) -> 0 | DI17: TER A: TK/0 TK/1 K/0 | DJ17: 11600001 | DK17: s.d. | DL17: 12500000 | DM17: 0.04 | DN17: =IF(DI17=DJ$2,"OK","") -> OK | DO17: =IF(DK$2>=DJ17,"OK","") -> OK | DP17: =IF(DK$2<=DL17,"OK","") | DQ17: =DN17&DO17&DP17 -> OKOK | DR17: =IF(DQ17="OKOKOK",DM17,0) -> 0
C18: - Pegawai tetap dan Pensiunan | E18: atas semua penghasilannya | N18: TER A: TK/0 TK/1 K/0 | O18: 12500001 | P18: s.d. | Q18: 13750000 | R18: 0.05 | S18: =IF(N18=O$2,"OK","") -> OK | T18: =IF(P$2>=O18,"OK","") | U18: =IF(P$2<=Q18,"OK","") -> OK | V18: =S18&T18&U18 -> OKOK | W18: =IF(V18="OKOKOK",R18,0) -> 0 | Y18: TER A: TK/0 TK/1 K/0 | Z18: 12500001 | AA18: s.d. | AB18: 13750000 | AC18: 0.05 | AD18: =IF(Y18=Z$2,"OK","") | AE18: =IF(AA$2>=Z18,"OK","") -> OK | AF18: =IF(AA$2<=AB18,"OK","") | AG18: =AD18&AE18&AF18 -> OK | AH18: =IF(AG18="OKOKOK",AC18,0) -> 0 | AJ18: TER A: TK/0 TK/1 K/0 | AK18: 12500001 | AL18: s.d. | AM18: 13750000 | AN18: 0.05 | AO18: =IF(AJ18=AK$2,"OK","") | AP18: =IF(AL$2>=AK18,"OK","") -> OK | AQ18: =IF(AL$2<=AM18,"OK","") | AR18: =AO18&AP18&AQ18 -> OK | AS18: =IF(AR18="OKOKOK",AN18,0) -> 0 | AU18: TER A: TK/0 TK/1 K/0 | AV18: 12500001 | AW18: s.d. | AX18: 13750000 | AY18: 0.05 | AZ18: =IF(AU18=AV$2,"OK","") -> OK | BA18: =IF(AW$2>=AV18,"OK","") -> OK | BB18: =IF(AW$2<=AX18,"OK","") | BC18: =AZ18&BA18&BB18 -> OKOK | BD18: =IF(BC18="OKOKOK",AY18,0) -> 0 | BF18: TER A: TK/0 TK/1 K/0 | BG18: 12500001 | BH18: s.d. | BI18: 13750000 | BJ18: 0.05 | BK18: =IF(BF18=BG$2,"OK","") | BL18: =IF(BH$2>=BG18,"OK","") -> OK | BM18: =IF(BH$2<=BI18,"OK","") | BN18: =BK18&BL18&BM18 -> OK | BO18: =IF(BN18="OKOKOK",BJ18,0) -> 0 | BQ18: TER A: TK/0 TK/1 K/0 | BR18: 12500001 | BS18: s.d. | BT18: 13750000 | BU18: 0.05 | BV18: =IF(BQ18=BR$2,"OK","") | BW18: =IF(BS$2>=BR18,"OK","") -> OK | BX18: =IF(BS$2<=BT18,"OK","") | BY18: =BV18&BW18&BX18 -> OK | BZ18: =IF(BY18="OKOKOK",BU18,0) -> 0 | CB18: TER A: TK/0 TK/1 K/0 | CC18: 12500001 | CD18: s.d. | CE18: 13750000 | CF18: 0.05 | CG18: =IF(CB18=CC$2,"OK","") -> OK | CH18: =IF(CD$2>=CC18,"OK","") -> OK | CI18: =IF(CD$2<=CE18,"OK","") | CJ18: =CG18&CH18&CI18 -> OKOK | CK18: =IF(CJ18="OKOKOK",CF18,0) -> 0 | CM18: TER A: TK/0 TK/1 K/0 | CN18: 12500001 | CO18: s.d. | CP18: 13750000 | CQ18: 0.05 | CR18: =IF(CM18=CN$2,"OK","") | CS18: =IF(CO$2>=CN18,"OK","") -> OK | CT18: =IF(CO$2<=CP18,"OK","") | CU18: =CR18&CS18&CT18 -> OK | CV18: =IF(CU18="OKOKOK",CQ18,0) -> 0 | CX18: TER A: TK/0 TK/1 K/0 | CY18: 12500001 | CZ18: s.d. | DA18: 13750000 | DB18: 0.05 | DC18: =IF(CX18=CY$2,"OK","") | DD18: =IF(CZ$2>=CY18,"OK","") -> OK | DE18: =IF(CZ$2<=DA18,"OK","") | DF18: =DC18&DD18&DE18 -> OK | DG18: =IF(DF18="OKOKOK",DB18,0) -> 0 | DI18: TER A: TK/0 TK/1 K/0 | DJ18: 12500001 | DK18: s.d. | DL18: 13750000 | DM18: 0.05 | DN18: =IF(DI18=DJ$2,"OK","") -> OK | DO18: =IF(DK$2>=DJ18,"OK","") -> OK | DP18: =IF(DK$2<=DL18,"OK","") | DQ18: =DN18&DO18&DP18 -> OKOK | DR18: =IF(DQ18="OKOKOK",DM18,0) -> 0
C19: - Pegawai tidak tetap yang dibayar BULANAN | E19: atas upahnya | N19: TER A: TK/0 TK/1 K/0 | O19: 13750001 | P19: s.d. | Q19: 15100000 | R19: 0.06 | S19: =IF(N19=O$2,"OK","") -> OK | T19: =IF(P$2>=O19,"OK","") | U19: =IF(P$2<=Q19,"OK","") -> OK | V19: =S19&T19&U19 -> OKOK | W19: =IF(V19="OKOKOK",R19,0) -> 0 | Y19: TER A: TK/0 TK/1 K/0 | Z19: 13750001 | AA19: s.d. | AB19: 15100000 | AC19: 0.06 | AD19: =IF(Y19=Z$2,"OK","") | AE19: =IF(AA$2>=Z19,"OK","") -> OK | AF19: =IF(AA$2<=AB19,"OK","") -> OK | AG19: =AD19&AE19&AF19 -> OKOK | AH19: =IF(AG19="OKOKOK",AC19,0) -> 0 | AJ19: TER A: TK/0 TK/1 K/0 | AK19: 13750001 | AL19: s.d. | AM19: 15100000 | AN19: 0.06 | AO19: =IF(AJ19=AK$2,"OK","") | AP19: =IF(AL$2>=AK19,"OK","") -> OK | AQ19: =IF(AL$2<=AM19,"OK","") | AR19: =AO19&AP19&AQ19 -> OK | AS19: =IF(AR19="OKOKOK",AN19,0) -> 0 | AU19: TER A: TK/0 TK/1 K/0 | AV19: 13750001 | AW19: s.d. | AX19: 15100000 | AY19: 0.06 | AZ19: =IF(AU19=AV$2,"OK","") -> OK | BA19: =IF(AW$2>=AV19,"OK","") -> OK | BB19: =IF(AW$2<=AX19,"OK","") | BC19: =AZ19&BA19&BB19 -> OKOK | BD19: =IF(BC19="OKOKOK",AY19,0) -> 0 | BF19: TER A: TK/0 TK/1 K/0 | BG19: 13750001 | BH19: s.d. | BI19: 15100000 | BJ19: 0.06 | BK19: =IF(BF19=BG$2,"OK","") | BL19: =IF(BH$2>=BG19,"OK","") -> OK | BM19: =IF(BH$2<=BI19,"OK","") | BN19: =BK19&BL19&BM19 -> OK | BO19: =IF(BN19="OKOKOK",BJ19,0) -> 0 | BQ19: TER A: TK/0 TK/1 K/0 | BR19: 13750001 | BS19: s.d. | BT19: 15100000 | BU19: 0.06 | BV19: =IF(BQ19=BR$2,"OK","") | BW19: =IF(BS$2>=BR19,"OK","") -> OK | BX19: =IF(BS$2<=BT19,"OK","") | BY19: =BV19&BW19&BX19 -> OK | BZ19: =IF(BY19="OKOKOK",BU19,0) -> 0 | CB19: TER A: TK/0 TK/1 K/0 | CC19: 13750001 | CD19: s.d. | CE19: 15100000 | CF19: 0.06 | CG19: =IF(CB19=CC$2,"OK","") -> OK | CH19: =IF(CD$2>=CC19,"OK","") -> OK | CI19: =IF(CD$2<=CE19,"OK","") | CJ19: =CG19&CH19&CI19 -> OKOK | CK19: =IF(CJ19="OKOKOK",CF19,0) -> 0 | CM19: TER A: TK/0 TK/1 K/0 | CN19: 13750001 | CO19: s.d. | CP19: 15100000 | CQ19: 0.06 | CR19: =IF(CM19=CN$2,"OK","") | CS19: =IF(CO$2>=CN19,"OK","") -> OK | CT19: =IF(CO$2<=CP19,"OK","") | CU19: =CR19&CS19&CT19 -> OK | CV19: =IF(CU19="OKOKOK",CQ19,0) -> 0 | CX19: TER A: TK/0 TK/1 K/0 | CY19: 13750001 | CZ19: s.d. | DA19: 15100000 | DB19: 0.06 | DC19: =IF(CX19=CY$2,"OK","") | DD19: =IF(CZ$2>=CY19,"OK","") -> OK | DE19: =IF(CZ$2<=DA19,"OK","") | DF19: =DC19&DD19&DE19 -> OK | DG19: =IF(DF19="OKOKOK",DB19,0) -> 0 | DI19: TER A: TK/0 TK/1 K/0 | DJ19: 13750001 | DK19: s.d. | DL19: 15100000 | DM19: 0.06 | DN19: =IF(DI19=DJ$2,"OK","") -> OK | DO19: =IF(DK$2>=DJ19,"OK","") -> OK | DP19: =IF(DK$2<=DL19,"OK","") | DQ19: =DN19&DO19&DP19 -> OKOK | DR19: =IF(DQ19="OKOKOK",DM19,0) -> 0
C20: - Pegawai tidak tetap yang dibayar tidak BULANAN | E20: penghasilan 0 s.d 2,5 Jt per Hari | N20: TER A: TK/0 TK/1 K/0 | O20: 15100001 | P20: s.d. | Q20: 16950000 | R20: 0.07 | S20: =IF(N20=O$2,"OK","") -> OK | T20: =IF(P$2>=O20,"OK","") | U20: =IF(P$2<=Q20,"OK","") -> OK | V20: =S20&T20&U20 -> OKOK | W20: =IF(V20="OKOKOK",R20,0) -> 0 | Y20: TER A: TK/0 TK/1 K/0 | Z20: 15100001 | AA20: s.d. | AB20: 16950000 | AC20: 0.07 | AD20: =IF(Y20=Z$2,"OK","") | AE20: =IF(AA$2>=Z20,"OK","") | AF20: =IF(AA$2<=AB20,"OK","") -> OK | AG20: =AD20&AE20&AF20 -> OK | AH20: =IF(AG20="OKOKOK",AC20,0) -> 0 | AJ20: TER A: TK/0 TK/1 K/0 | AK20: 15100001 | AL20: s.d. | AM20: 16950000 | AN20: 0.07 | AO20: =IF(AJ20=AK$2,"OK","") | AP20: =IF(AL$2>=AK20,"OK","") -> OK | AQ20: =IF(AL$2<=AM20,"OK","") | AR20: =AO20&AP20&AQ20 -> OK | AS20: =IF(AR20="OKOKOK",AN20,0) -> 0 | AU20: TER A: TK/0 TK/1 K/0 | AV20: 15100001 | AW20: s.d. | AX20: 16950000 | AY20: 0.07 | AZ20: =IF(AU20=AV$2,"OK","") -> OK | BA20: =IF(AW$2>=AV20,"OK","") -> OK | BB20: =IF(AW$2<=AX20,"OK","") | BC20: =AZ20&BA20&BB20 -> OKOK | BD20: =IF(BC20="OKOKOK",AY20,0) -> 0 | BF20: TER A: TK/0 TK/1 K/0 | BG20: 15100001 | BH20: s.d. | BI20: 16950000 | BJ20: 0.07 | BK20: =IF(BF20=BG$2,"OK","") | BL20: =IF(BH$2>=BG20,"OK","") -> OK | BM20: =IF(BH$2<=BI20,"OK","") | BN20: =BK20&BL20&BM20 -> OK | BO20: =IF(BN20="OKOKOK",BJ20,0) -> 0 | BQ20: TER A: TK/0 TK/1 K/0 | BR20: 15100001 | BS20: s.d. | BT20: 16950000 | BU20: 0.07 | BV20: =IF(BQ20=BR$2,"OK","") | BW20: =IF(BS$2>=BR20,"OK","") -> OK | BX20: =IF(BS$2<=BT20,"OK","") | BY20: =BV20&BW20&BX20 -> OK | BZ20: =IF(BY20="OKOKOK",BU20,0) -> 0 | CB20: TER A: TK/0 TK/1 K/0 | CC20: 15100001 | CD20: s.d. | CE20: 16950000 | CF20: 0.07 | CG20: =IF(CB20=CC$2,"OK","") -> OK | CH20: =IF(CD$2>=CC20,"OK","") -> OK | CI20: =IF(CD$2<=CE20,"OK","") | CJ20: =CG20&CH20&CI20 -> OKOK | CK20: =IF(CJ20="OKOKOK",CF20,0) -> 0 | CM20: TER A: TK/0 TK/1 K/0 | CN20: 15100001 | CO20: s.d. | CP20: 16950000 | CQ20: 0.07 | CR20: =IF(CM20=CN$2,"OK","") | CS20: =IF(CO$2>=CN20,"OK","") -> OK | CT20: =IF(CO$2<=CP20,"OK","") | CU20: =CR20&CS20&CT20 -> OK | CV20: =IF(CU20="OKOKOK",CQ20,0) -> 0 | CX20: TER A: TK/0 TK/1 K/0 | CY20: 15100001 | CZ20: s.d. | DA20: 16950000 | DB20: 0.07 | DC20: =IF(CX20=CY$2,"OK","") | DD20: =IF(CZ$2>=CY20,"OK","") -> OK | DE20: =IF(CZ$2<=DA20,"OK","") | DF20: =DC20&DD20&DE20 -> OK | DG20: =IF(DF20="OKOKOK",DB20,0) -> 0 | DI20: TER A: TK/0 TK/1 K/0 | DJ20: 15100001 | DK20: s.d. | DL20: 16950000 | DM20: 0.07 | DN20: =IF(DI20=DJ$2,"OK","") -> OK | DO20: =IF(DK$2>=DJ20,"OK","") -> OK | DP20: =IF(DK$2<=DL20,"OK","") | DQ20: =DN20&DO20&DP20 -> OKOK | DR20: =IF(DQ20="OKOKOK",DM20,0) -> 0
C21: - Anggota Dewan Komisaris/Pengawas | E21: atas honor | N21: TER A: TK/0 TK/1 K/0 | O21: 16950001 | P21: s.d. | Q21: 19750000 | R21: 0.08 | S21: =IF(N21=O$2,"OK","") -> OK | T21: =IF(P$2>=O21,"OK","") | U21: =IF(P$2<=Q21,"OK","") -> OK | V21: =S21&T21&U21 -> OKOK | W21: =IF(V21="OKOKOK",R21,0) -> 0 | Y21: TER A: TK/0 TK/1 K/0 | Z21: 16950001 | AA21: s.d. | AB21: 19750000 | AC21: 0.08 | AD21: =IF(Y21=Z$2,"OK","") | AE21: =IF(AA$2>=Z21,"OK","") | AF21: =IF(AA$2<=AB21,"OK","") -> OK | AG21: =AD21&AE21&AF21 -> OK | AH21: =IF(AG21="OKOKOK",AC21,0) -> 0 | AJ21: TER A: TK/0 TK/1 K/0 | AK21: 16950001 | AL21: s.d. | AM21: 19750000 | AN21: 0.08 | AO21: =IF(AJ21=AK$2,"OK","") | AP21: =IF(AL$2>=AK21,"OK","") -> OK | AQ21: =IF(AL$2<=AM21,"OK","") | AR21: =AO21&AP21&AQ21 -> OK | AS21: =IF(AR21="OKOKOK",AN21,0) -> 0 | AU21: TER A: TK/0 TK/1 K/0 | AV21: 16950001 | AW21: s.d. | AX21: 19750000 | AY21: 0.08 | AZ21: =IF(AU21=AV$2,"OK","") -> OK | BA21: =IF(AW$2>=AV21,"OK","") -> OK | BB21: =IF(AW$2<=AX21,"OK","") | BC21: =AZ21&BA21&BB21 -> OKOK | BD21: =IF(BC21="OKOKOK",AY21,0) -> 0 | BF21: TER A: TK/0 TK/1 K/0 | BG21: 16950001 | BH21: s.d. | BI21: 19750000 | BJ21: 0.08 | BK21: =IF(BF21=BG$2,"OK","") | BL21: =IF(BH$2>=BG21,"OK","") -> OK | BM21: =IF(BH$2<=BI21,"OK","") | BN21: =BK21&BL21&BM21 -> OK | BO21: =IF(BN21="OKOKOK",BJ21,0) -> 0 | BQ21: TER A: TK/0 TK/1 K/0 | BR21: 16950001 | BS21: s.d. | BT21: 19750000 | BU21: 0.08 | BV21: =IF(BQ21=BR$2,"OK","") | BW21: =IF(BS$2>=BR21,"OK","") -> OK | BX21: =IF(BS$2<=BT21,"OK","") | BY21: =BV21&BW21&BX21 -> OK | BZ21: =IF(BY21="OKOKOK",BU21,0) -> 0 | CB21: TER A: TK/0 TK/1 K/0 | CC21: 16950001 | CD21: s.d. | CE21: 19750000 | CF21: 0.08 | CG21: =IF(CB21=CC$2,"OK","") -> OK | CH21: =IF(CD$2>=CC21,"OK","") -> OK | CI21: =IF(CD$2<=CE21,"OK","") | CJ21: =CG21&CH21&CI21 -> OKOK | CK21: =IF(CJ21="OKOKOK",CF21,0) -> 0 | CM21: TER A: TK/0 TK/1 K/0 | CN21: 16950001 | CO21: s.d. | CP21: 19750000 | CQ21: 0.08 | CR21: =IF(CM21=CN$2,"OK","") | CS21: =IF(CO$2>=CN21,"OK","") -> OK | CT21: =IF(CO$2<=CP21,"OK","") | CU21: =CR21&CS21&CT21 -> OK | CV21: =IF(CU21="OKOKOK",CQ21,0) -> 0 | CX21: TER A: TK/0 TK/1 K/0 | CY21: 16950001 | CZ21: s.d. | DA21: 19750000 | DB21: 0.08 | DC21: =IF(CX21=CY$2,"OK","") | DD21: =IF(CZ$2>=CY21,"OK","") -> OK | DE21: =IF(CZ$2<=DA21,"OK","") | DF21: =DC21&DD21&DE21 -> OK | DG21: =IF(DF21="OKOKOK",DB21,0) -> 0 | DI21: TER A: TK/0 TK/1 K/0 | DJ21: 16950001 | DK21: s.d. | DL21: 19750000 | DM21: 0.08 | DN21: =IF(DI21=DJ$2,"OK","") -> OK | DO21: =IF(DK$2>=DJ21,"OK","") -> OK | DP21: =IF(DK$2<=DL21,"OK","") | DQ21: =DN21&DO21&DP21 -> OKOK | DR21: =IF(DQ21="OKOKOK",DM21,0) -> 0
