Workbook

Sheet ⚙ Pengaturan
B2: PENGATURAN APLIKASI RANCANGAN ANGGARAN ARKAS
B3: SMA Negeri 1 Cigalontang — Provinsi Jawa Barat
B5: 🏫 Nama Sekolah | E5: SMA Negeri 1 Cigalontang
B6: 🔢 NPSN | E6: 20212066
B7: 📍 Alamat | E7: Jl. Cigalontang, Kec. Cigalontang
B8: 🗺️ Kabupaten/Kota | E8: Kabupaten Tasikmalaya
B9: 🗺️ Provinsi | E9: Jawa Barat
B10: 📅 Tahun Anggaran | E10: 2026
B11: 👤 Kepala Sekolah
B12: 💼 Bendahara BOSP
B13: 💼 Bendahara BOPD
B14: 👥 Jumlah Siswa (awal) | E14: 0
B15: 💰 Total Alokasi BOSP (Rp) | E15: 0
B16: 💰 Total Alokasi BOPD (Rp) | E16: 0
B17: 🗓️ Tanggal Dibuat | E17: 46129.238
B19: ⚠️ Isi Total Alokasi BOSP (E15) dan BOPD (E16) dengan benar — digunakan untuk perhitungan peringatan batas anggaran di sheet Kontrol Batas.

Sheet 📋 Kode Kegiatan
A1: REFERENSI KODE KEGIATAN ARKAS
A2: Permendikbudristek No. 2 Tahun 2022 tentang BOSP — berlaku untuk BOSP dan BOPD
A4: Kode | B4: Nama Komponen / Kegiatan | C4: Keterangan / Contoh Kegiatan | D4: Sumber Dana
A5: 1 | B5: Penerimaan Peserta Didik Baru | C5: PPDB, seleksi, orientasi siswa baru | D5: BOSP, BOPD
A6: 2 | B6: Pengembangan Perpustakaan | C6: Buku teks, buku pengayaan, langganan jurnal/e-book | D6: BOSP, BOPD
A7: 3 | B7: Kegiatan Pembelajaran dan Ekstrakurikuler | C7: Praktek, lab, KBM, ekskul, OSIS, Pramuka, PMR | D7: BOSP, BOPD
A8: 4 | B8: Asesmen/Evaluasi Pembelajaran dan Rapor | C8: PH, PTS, PAS, ANBK, SKL, rapor digital | D8: BOSP, BOPD
A9: 5 | B9: Administrasi Sekolah dan Pengelolaan | C9: ATK, pengelolaan keuangan, asuransi, pelaporan | D9: BOSP, BOPD
A10: 6 | B10: Pengembangan Profesi GTK | C10: Diklat, seminar, workshop, MGMP, IHT, magang | D10: BOSP, BOPD
A11: 7 | B11: Langganan Daya dan Jasa | C11: Listrik, air, telepon, internet, pajak | D11: BOSP, BOPD
A12: 8 | B12: Pemeliharaan Sarana dan Prasarana | C12: Perbaikan gedung, peralatan, mebeler, kendaraan | D12: BOSP, BOPD
A13: 9 | B13: Penyediaan Alat Multi Media Pembelajaran | C13: Laptop, proyektor, printer, speaker, kamera | D13: BOSP, BOPD
A14: 10 | B14: Pembayaran Honor | C14: Honor GTT, PTT, dan tenaga non-ASN lainnya | D14: BOSP, BOPD
A15: 11 | B15: Kegiatan Peningkatan Kompetensi Keahlian | C15: Khusus SMK: prakerin, teaching factory, BKK | D15: BOSP, BOPD
... A17: 13 | B17: Pemberdayaan Masyarakat Sekitar Sekolah | C17: Komite, sosialisasi, kemitraan komunitas | D17: BOSP, BOPD

Sheet 📂 Kode Rekening
A1: REFERENSI KODE REKENING BELANJA — NASIONAL (BAS / SIPD)
A2: Digunakan untuk kegiatan yang dibiayai BOSP — Berlaku di semua provinsi
A4: Kode Rekening | B4: Uraian Rekening | C4: Kelompok Belanja | D4: Keterangan
A5: ▌ BARANG HABIS PAKAI
A6: 5.1.02.01.0001 | B6: Belanja Alat Tulis Kantor | C6: Barang Habis Pakai
A7: 5.1.02.01.0002 | B7: Belanja Alat Listrik dan Elektronik | C7: Barang Habis Pakai
A8: 5.1.02.01.0003 | B8: Belanja Perangko, Materai dan Benda Pos | C8: Barang Habis Pakai
A9: 5.1.02.01.0004 | B9: Belanja Peralatan Kebersihan dan Bahan Pembersih | C9: Barang Habis Pakai
A10: 5.1.02.01.0005 | B10: Belanja Bahan Bakar Minyak/Gas | C10: Barang Habis Pakai
A11: 5.1.02.01.0006 | B11: Belanja Barang Pakai Habis Lainnya | C11: Barang Habis Pakai
A12: ▌ BAHAN/MATERIAL
A13: 5.1.02.02.0001 | B13: Belanja Buku Teks Pelajaran | C13: Bahan/Material
A14: 5.1.02.02.0002 | B14: Belanja Buku Pengayaan / Referensi | C14: Bahan/Material
A15: 5.1.02.02.0003 | B15: Belanja Bahan Praktik / Laboratorium | C15: Bahan/Material
A16: 5.1.02.02.0004 | B16: Belanja Bahan Bangunan / Material Pemeliharaan | C16: Bahan/Material
A17: 5.1.02.02.0005 | B17: Belanja Bahan Lainnya | C17: Bahan/Material
A18: ▌ JASA KANTOR
A19: 5.1.02.03.0001 | B19: Belanja Jasa Listrik | C19: Jasa Kantor
A20: 5.1.02.03.0002 | B20: Belanja Jasa Air / PDAM | C20: Jasa Kantor
A21: 5.1.02.03.0003 | B21: Belanja Jasa Telepon | C21: Jasa Kantor
A22: 5.1.02.03.0004 | B22: Belanja Jasa Internet / Bandwidth | C22: Jasa Kantor
A23: 5.1.02.03.0005 | B23: Belanja Jasa Kebersihan / Keamanan | C23: Jasa Kantor
A24: 5.1.02.03.0006 | B24: Belanja Jasa Kantor Lainnya | C24: Jasa Kantor
A25: ▌ CETAK & PENGGANDAAN
A26: 5.1.02.06.0001 | B26: Belanja Cetak | C26: Cetak & Penggandaan
A27: 5.1.02.06.0002 | B27: Belanja Penggandaan / Fotokopi | C27: Cetak & Penggandaan
A28: ▌ SEWA
A29: 5.1.02.07.0001 | B29: Belanja Sewa Gedung / Aula / Ruangan | C29: Sewa
A30: 5.1.02.08.0001 | B30: Belanja Sewa Kendaraan | C30: Sewa
A31: 5.1.02.10.0001 | B31: Belanja Sewa Peralatan / Perlengkapan | C31: Sewa
A32: ▌ MAKAN & MINUM
A33: 5.1.02.11.0001 | B33: Belanja Makan dan Minum Rapat | C33: Makan & Minum
A34: 5.1.02.11.0002 | B34: Belanja Makan dan Minum Kegiatan | C34: Makan & Minum
A35: 5.1.02.11.0003 | B35: Belanja Makan dan Minum Tamu | C35: Makan & Minum
A36: ▌ PAKAIAN
A37: 5.1.02.14.0001 | B37: Belanja Pakaian Batik Tradisional | C37: Pakaian
A38: 5.1.02.14.0002 | B38: Belanja Pakaian Olahraga | C38: Pakaian
A39: 5.1.02.14.0003 | B39: Belanja Pakaian Kegiatan Khusus | C39: Pakaian
A40: ▌ PERJALANAN DINAS
A41: 5.1.02.15.0001 | B41: Belanja Perjalanan Dinas Dalam Daerah | C41: Perjalanan Dinas
...

Sheet 📂 Kode Rekening BOPD Jabar
A1: REFERENSI KODE REKENING BELANJA — BOPD PROVINSI JAWA BARAT
A2: Berdasarkan Pergub Jabar & SIPD Provinsi Jawa Barat — Khusus Dana BOPD SMA/SMK/SLB Negeri
A3: ⚠️ Catatan: Konfirmasi kode rekening final ke operator SIPD/BOPD Dinas Pendidikan Provinsi Jabar sebelum memasukkan ke sistem. Kode sub-rincian dapat berubah setiap tahun anggaran.
A5: Kode Rekening | B5: Uraian Rekening | C5: Kelompok Belanja | D5: Sumber Dana | E5: Keterangan
A6: ▌ BELANJA PEGAWAI BOPD
A7: 5.1.01.01.0001 | B7: Belanja Gaji / Honorarium GTT (Guru Tidak Tetap) | C7: Belanja Pegawai BOPD | D7: BOPD
A8: 5.1.01.01.0002 | B8: Belanja Gaji / Honorarium PTT (Pegawai Tidak Tetap) | C8: Belanja Pegawai BOPD | D8: BOPD
A9: 5.1.01.01.0003 | B9: Belanja Honorarium Tenaga Kependidikan Non-ASN | C9: Belanja Pegawai BOPD | D9: BOPD
A10: 5.1.01.02.0001 | B10: Belanja Tambahan Penghasilan (Tunjangan Daerah) | C10: Belanja Pegawai BOPD | D10: BOPD
A11: ▌ BARANG HABIS PAKAI BOPD
A12: 5.1.02.01.0011 | B12: Belanja ATK (BOPD) | C12: Barang Habis Pakai BOPD | D12: BOPD
A13: 5.1.02.01.0012 | B13: Belanja Bahan Praktik Siswa (BOPD) | C13: Barang Habis Pakai BOPD | D13: BOPD
A14: 5.1.02.01.0013 | B14: Belanja Bahan Kebersihan Lingkungan Sekolah (BOPD) | C14: Barang Habis Pakai BOPD | D14: BOPD
A15: ▌ BAHAN/MATERIAL BOPD
A16: 5.1.02.02.0011 | B16: Belanja Buku Pegangan Guru (BOPD) | C16: Bahan/Material BOPD | D16: BOPD
A17: 5.1.02.02.0012 | B17: Belanja Modul/LKS Siswa (BOPD) | C17: Bahan/Material BOPD | D17: BOPD
A18: ▌ JASA KANTOR BOPD
A19: 5.1.02.03.0011 | B19: Belanja Langganan Listrik (BOPD) | C19: Jasa Kantor BOPD | D19: BOPD
A20: 5.1.02.03.0012 | B20: Belanja Langganan Air (BOPD) | C20: Jasa Kantor BOPD | D20: BOPD
A21: 5.1.02.03.0013 | B21: Belanja Langganan Internet / Speedy (BOPD) | C21: Jasa Kantor BOPD | D21: BOPD
A22: ▌ CETAK & PENGGANDAAN BOPD
A23: 5.1.02.06.0011 | B23: Belanja Cetak Formulir / Administrasi (BOPD) | C23: Cetak & Penggandaan BOPD | D23: BOPD
A24: 5.1.02.06.0012 | B24: Belanja Penggandaan Soal Ulangan (BOPD) | C24: Cetak & Penggandaan BOPD | D24: BOPD
A25: ▌ MAKAN & MINUM BOPD
A26: 5.1.02.11.0011 | B26: Belanja Makan dan Minum Rapat Dinas (BOPD) | C26: Makan & Minum BOPD | D26: BOPD
A27: 5.1.02.11.0012 | B27: Belanja Makan dan Minum Kegiatan MPLS/PPDB (BOPD) | C27: Makan & Minum BOPD | D27: BOPD
A28: ▌ PERJALANAN DINAS BOPD
A29: 5.1.02.15.0011 | B29: Belanja Perjalanan Dinas Dalam Provinsi (BOPD) | C29: Perjalanan Dinas BOPD | D29: BOPD
A30: ▌ PELATIHAN BOPD
A31: 5.1.02.17.0011 | B31: Belanja Pelatihan / Workshop / IHT Guru (BOPD) | C31: Pelatihan BOPD | D31: BOPD
A32: 5.1.02.17.0012 | B32: Belanja MGMP / KKG / MKKS Tingkat Kab/Kota (BOPD) | C32: Pelatihan BOPD | D32: BOPD
A33: ▌ PEMELIHARAAN BOPD
A34: 5.1.02.20.0011 | B34: Belanja Rehab Ringan Gedung / Ruang Kelas (BOPD) | C34: Pemeliharaan BOPD | D34: BOPD
A35: 5.1.02.20.0012 | B35: Belanja Pemeliharaan Sanitasi / Toilet Sekolah (BOPD) | C35: Pemeliharaan BOPD | D35: BOPD
A36: 5.1.02.20.0013 | B36: Belanja Pemeliharaan Sarana TIK (BOPD) | C36: Pemeliharaan BOPD | D36: BOPD
A37: 5.1.02.20.0014 | B37: Belanja Cat / Pengecatan Gedung Sekolah (BOPD) | C37: Pemeliharaan BOPD | D37: BOPD
A38: ▌ KEGIATAN KHUSUS BOPD JABAR
A39: 5.1.02.99.0001 | B39: Belanja Kegiatan PDBK / Inklusi (BOPD) | C39: Kegiatan Khusus BOPD Jabar | D39: BOPD
A40: 5.1.02.99.0002 | B40: Belanja Kegiatan Penguatan Profil Pelajar Pancasila (BOPD) | C40: Kegiatan Khusus BOPD Jabar | D40: BOPD
A41: 5.1.02.99.0003 | B41: Belanja Kegiatan Pencegahan Perundungan/Narkoba (BOPD) | C41: Kegiatan Khusus BOPD Jabar | D41: BOPD
...

Sheet ✏️ Rancangan Anggaran
A1: RANCANGAN KEGIATAN DAN ANGGARAN SEKOLAH (RKAS)
A2: SMA Negeri 1 Cigalontang — Kabupaten Tasikmalaya — Provinsi Jawa Barat
A3: Tahun Anggaran 2026 | Sumber Dana: BOSP & BOPD | 150 baris tersedia
B4: KEGIATAN | E4: BELANJA | I4: ANGGARAN | N4: JADWAL & STATUS | Q4: REALISASI
A5: No | B5: Kode Keg | C5: Nama Kegiatan | D5: Kode Rekening | E5: Uraian Rekening | F5: Uraian Rincian (detail barang/jasa) | G5: Vol | H5: Sat | I5: Harga Satuan (Rp) | J5: Jumlah (Rp) | K5: Sumber Dana | L5: Alokasi BOSP (Rp) | M5: Alokasi BOPD (Rp) | N5: Semester | O5: Tri- wulan | P5: Status Rencana | Q5: Realisasi (Rp) | R5: % Realisasi | S5: Sisa Anggaran (Rp) | T5: Status Realisasi | U5: Keterangan
A6: 1 | J6: =IF(AND(G6<>"",I6<>""),G6*I6,0) | R6: =IF(J6>0,Q6/J6,0) | S6: =IF(J6>0,J6-Q6,0)
A7: 2 | J7: =IF(AND(G7<>"",I7<>""),G7*I7,0) | R7: =IF(J7>0,Q7/J7,0) | S7: =IF(J7>0,J7-Q7,0)
A8: 3 | J8: =IF(AND(G8<>"",I8<>""),G8*I8,0) | R8: =IF(J8>0,Q8/J8,0) | S8: =IF(J8>0,J8-Q8,0)
A9: 4 | J9: =IF(AND(G9<>"",I9<>""),G9*I9,0) | R9: =IF(J9>0,Q9/J9,0) | S9: =IF(J9>0,J9-Q9,0)
A10: 5 | J10: =IF(AND(G10<>"",I10<>""),G10*I10,0) | R10: =IF(J10>0,Q10/J10,0) | S10: =IF(J10>0,J10-Q10,0)
A11: 6 | J11: =IF(AND(G11<>"",I11<>""),G11*I11,0) | R11: =IF(J11>0,Q11/J11,0) | S11: =IF(J11>0,J11-Q11,0)
A12: 7 | J12: =IF(AND(G12<>"",I12<>""),G12*I12,0) | R12: =IF(J12>0,Q12/J12,0) | S12: =IF(J12>0,J12-Q12,0)
A13: 8 | J13: =IF(AND(G13<>"",I13<>""),G13*I13,0) | R13: =IF(J13>0,Q13/J13,0) | S13: =IF(J13>0,J13-Q13,0)
A14: 9 | J14: =IF(AND(G14<>"",I14<>""),G14*I14,0) | R14: =IF(J14>0,Q14/J14,0) | S14: =IF(J14>0,J14-Q14,0)
A15: 10 | J15: =IF(AND(G15<>"",I15<>""),G15*I15,0) | R15: =IF(J15>0,Q15/J15,0) | S15: =IF(J15>0,J15-Q15,0)
A16: 11 | J16: =IF(AND(G16<>"",I16<>""),G16*I16,0) | R16: =IF(J16>0,Q16/J16,0) | S16: =IF(J16>0,J16-Q16,0)
A17: 12 | J17: =IF(AND(G17<>"",I17<>""),G17*I17,0) | R17: =IF(J17>0,Q17/J17,0) | S17: =IF(J17>0,J17-Q17,0)
... A155: 150 | J155: =IF(AND(G155<>"",I155<>""),G155*I155,0) | R155: =IF(J155>0,Q155/J155,0) | S155: =IF(J155>0,J155-Q155,0)
A156: TOTAL KESELURUHAN | J156: =SUM(J6:J155) | L156: =SUM(L6:L155) | M156: =SUM(M6:M155) | Q156: =SUM(Q6:Q155) | S156: =SUM(S6:S155)

Sheet ⚠️ Kontrol Batas BOSP
A1: KONTROL BATAS PENGGUNAAN DANA BOSP
A2: Berdasarkan Permendikbudristek No. 2/2022 & Juknis BOSP 2024 — Peringatan otomatis jika anggaran melampaui/tidak mencapai batas
A4: 📌 Informasi Alokasi (dari sheet Pengaturan)
A5: Total Alokasi BOSP (Rp) | C5: ='⚙ Pengaturan'!E15
A6: Total Alokasi BOPD (Rp) | C6: ='⚙ Pengaturan'!E16
A7: Total Rencana BOSP (dari Rancangan) | C7: ='✏️ Rancangan Anggaran'!L156
A8: Total Rencana BOPD (dari Rancangan) | C8: ='✏️ Rancangan Anggaran'!M156
A9: Sisa Alokasi BOSP (Rp) | C9: =C5-C7
A10: Sisa Alokasi BOPD (Rp) | C10: =C6-C8
A12: 🚦 Tabel Kontrol Batas Per Komponen Kegiatan
A13: Komponen | B13: Jenis Batas | C13: Batas (%) Regulasi | D13: Nilai Batas (Rp) | E13: Rencana (Rp) | F13: % Rencana thd BOSP | G13: Status | H13: Regulasi / Catatan
A14: Pembayaran Honor (Kode 10) | B14: MAKSIMUM | C14: 0.5 | D14: =0.5*C5 | E14: =SUMPRODUCT(('✏️ Rancangan Anggaran'!B6:B155="10")*('✏️ Rancangan Anggaran'!L6:L155)) | F14: =IF(C5>0,E14/C5,0) | G14: =IF(E14=0,"— Belum Diisi",IF(E14>D14,"⛔ MELEBIHI BATAS","✅ Aman")) | H14: Honor GTT/PTT tidak boleh melebihi 50% dari total BOSP yang diterima dalam satu tahun anggaran. [Permendikbudristek No. 2/2022 Pasal 9 ayat (2)]
A15: Pengembangan Perpustakaan / Buku (Kode 2) | B15: MINIMUM | C15: 0.05 | D15: =0.05*C5 | E15: =SUMPRODUCT(('✏️ Rancangan Anggaran'!B6:B155="2")*('✏️ Rancangan Anggaran'!L6:L155)) | F15: =IF(C5>0,E15/C5,0) | G15: =IF(E15=0,"— Belum Diisi",IF(E15<D15,"⚠️ DI BAWAH BATAS","✅ Terpenuhi")) | H15: Sekolah dianjurkan mengalokasikan minimal 5% BOSP untuk pengadaan buku guna memenuhi rasio 1 buku per siswa per mata pelajaran. [Permendikbudristek No. 2/2022 Lampiran I]
A16: Pemeliharaan Sarana dan Prasarana (Kode 8) | B16: MAKSIMUM | C16: 0.2 | D16: =0.2*C5 | E16: =SUMPRODUCT(('✏️ Rancangan Anggaran'!B6:B155="8")*('✏️ Rancangan Anggaran'!L6:L155)) | F16: =IF(C5>0,E16/C5,0) | G16: =IF(E16=0,"— Belum Diisi",IF(E16>D16,"⛔ MELEBIHI BATAS","✅ Aman")) | H16: Pemeliharaan sapras disarankan tidak melebihi 20% BOSP. Jika perlu rehab berat, gunakan sumber dana BOPD atau DAK Fisik. [Permendikbudristek No. 2/2022 Lampiran I + Juknis BOSP 2024]
A17: Pembelajaran & Ekstrakurikuler (Kode 3) | B17: MINIMUM | C17: 0.1 | D17: =0.1*C5 | E17: =SUMPRODUCT(('✏️ Rancangan Anggaran'!B6:B155="3")*('✏️ Rancangan Anggaran'!L6:L155)) | F17: =IF(C5>0,E17/C5,0) | G17: =IF(E17=0,"— Belum Diisi",IF(E17<D17,"⚠️ DI BAWAH BATAS","✅ Terpenuhi")) | H17: Kegiatan pembelajaran adalah inti penggunaan BOSP. Disarankan minimal 10% dialokasikan untuk komponen ini. [Permendikbudristek No. 2/2022 Lampiran I]
A19: 🚫 LARANGAN PENGGUNAAN DANA BOSP (tidak boleh sama sekali)
A20: ✗ Membangun gedung/ruangan baru (kecuali toilet/WC yang belum ada)
A21: ✗ Membayar gaji/tunjangan PNS/PPPK yang sudah ditanggung APBN/APBD
A22: ✗ Investasi saham atau membayar cicilan/bunga utang
A23: ✗ Membeli pakaian/seragam untuk siswa maupun guru
A24: ✗ Membayar iuran/dana untuk kepentingan pribadi
A25: ✗ Uang transpor untuk siswa reguler (bukan afirmasi)
A26: ✗ Membeli aset tetap bernilai di atas Rp 1.500.000 dengan sumber non-modal (harus kode 5.2.xx)

Sheet 📊 Rekap BOSP
A1: REKAPITULASI ANGGARAN — BOSP
A2: SMA Negeri 1 Cigalontang | Tahun Anggaran 2026 | Dana: BOSP
A4: No | B4: Kode | C4: Nama Kegiatan | D4: Rencana BOSP (Rp) | E4: Realisasi BOSP (Rp) | F4: % Rencana | G4: % Realisasi
A5: 1 | B5: 1 | C5: Penerimaan Peserta Didik Baru | D5: =SUMPRODUCT(('✏️ Rancangan Anggaran'!B6:B155=B5)*('✏️ Rancangan Anggaran'!L6:L155)) | E5: =SUMPRODUCT(('✏️ Rancangan Anggaran'!B6:B155=B5)*('✏️ Rancangan Anggaran'!K6:K155="BOSP")*('✏️ Rancangan Anggaran'!Q6:Q155)) | F5: =IF(D19<>0,D5/D19,0) | G5: =IF(D5>0,E5/D5,0)
A6: 2 | B6: 2 | C6: Pengembangan Perpustakaan | D6: =SUMPRODUCT(('✏️ Rancangan Anggaran'!B6:B155=B6)*('✏️ Rancangan Anggaran'!L6:L155)) | E6: =SUMPRODUCT(('✏️ Rancangan Anggaran'!B6:B155=B6)*('✏️ Rancangan Anggaran'!K6:K155="BOSP")*('✏️ Rancangan Anggaran'!Q6:Q155)) | F6: =IF(D19<>0,D6/D19,0) | G6: =IF(D6>0,E6/D6,0)
A7: 3 | B7: 3 | C7: Kegiatan Pembelajaran dan Ekstrakurikuler | D7: =SUMPRODUCT(('✏️ Rancangan Anggaran'!B6:B155=B7)*('✏️ Rancangan Anggaran'!L6:L155)) | E7: =SUMPRODUCT(('✏️ Rancangan Anggaran'!B6:B155=B7)*('✏️ Rancangan Anggaran'!K6:K155="BOSP")*('✏️ Rancangan Anggaran'!Q6:Q155)) | F7: =IF(D19<>0,D7/D19,0) | G7: =IF(D7>0,E7/D7,0)
A8: 4 | B8: 4 | C8: Asesmen/Evaluasi Pembelajaran dan Rapor | D8: =SUMPRODUCT(('✏️ Rancangan Anggaran'!B6:B155=B8)*('✏️ Rancangan Anggaran'!L6:L155)) | E8: =SUMPRODUCT(('✏️ Rancangan Anggaran'!B6:B155=B8)*('✏️ Rancangan Anggaran'!K6:K155="BOSP")*('✏️ Rancangan Anggaran'!Q6:Q155)) | F8: =IF(D19<>0,D8/D19,0) | G8: =IF(D8>0,E8/D8,0)
A9: 5 | B9: 5 | C9: Administrasi Sekolah dan Pengelolaan | D9: =SUMPRODUCT(('✏️ Rancangan Anggaran'!B6:B155=B9)*('✏️ Rancangan Anggaran'!L6:L155)) | E9: =SUMPRODUCT(('✏️ Rancangan Anggaran'!B6:B155=B9)*('✏️ Rancangan Anggaran'!K6:K155="BOSP")*('✏️ Rancangan Anggaran'!Q6:Q155)) | F9: =IF(D19<>0,D9/D19,0) | G9: =IF(D9>0,E9/D9,0)
A10: 6 | B10: 6 | C10: Pengembangan Profesi GTK | D10: =SUMPRODUCT(('✏️ Rancangan Anggaran'!B6:B155=B10)*('✏️ Rancangan Anggaran'!L6:L155)) | E10: =SUMPRODUCT(('✏️ Rancangan Anggaran'!B6:B155=B10)*('✏️ Rancangan Anggaran'!K6:K155="BOSP")*('✏️ Rancangan Anggaran'!Q6:Q155)) | F10: =IF(D19<>0,D10/D19,0) | G10: =IF(D10>0,E10/D10,0)
A11: 7 | B11: 7 | C11: Langganan Daya dan Jasa | D11: =SUMPRODUCT(('✏️ Rancangan Anggaran'!B6:B155=B11)*('✏️ Rancangan Anggaran'!L6:L155)) | E11: =SUMPRODUCT(('✏️ Rancangan Anggaran'!B6:B155=B11)*('✏️ Rancangan Anggaran'!K6:K155="BOSP")*('✏️ Rancangan Anggaran'!Q6:Q155)) | F11: =IF(D19<>0,D11/D19,0) | G11: =IF(D11>0,E11/D11,0)
A12: 8 | B12: 8 | C12: Pemeliharaan Sarana dan Prasarana | D12: =SUMPRODUCT(('✏️ Rancangan Anggaran'!B6:B155=B12)*('✏️ Rancangan Anggaran'!L6:L155)) | E12: =SUMPRODUCT(('✏️ Rancangan Anggaran'!B6:B155=B12)*('✏️ Rancangan Anggaran'!K6:K155="BOSP")*('✏️ Rancangan Anggaran'!Q6:Q155)) | F12: =IF(D19<>0,D12/D19,0) | G12: =IF(D12>0,E12/D12,0)
A13: 9 | B13: 9 | C13: Penyediaan Alat Multi Media Pembelajaran | D13: =SUMPRODUCT(('✏️ Rancangan Anggaran'!B6:B155=B13)*('✏️ Rancangan Anggaran'!L6:L155)) | E13: =SUMPRODUCT(('✏️ Rancangan Anggaran'!B6:B155=B13)*('✏️ Rancangan Anggaran'!K6:K155="BOSP")*('✏️ Rancangan Anggaran'!Q6:Q155)) | F13: =IF(D19<>0,D13/D19,0) | G13: =IF(D13>0,E13/D13,0)
A14: 10 | B14: 10 | C14: Pembayaran Honor | D14: =SUMPRODUCT(('✏️ Rancangan Anggaran'!B6:B155=B14)*('✏️ Rancangan Anggaran'!L6:L155)) | E14: =SUMPRODUCT(('✏️ Rancangan Anggaran'!B6:B155=B14)*('✏️ Rancangan Anggaran'!K6:K155="BOSP")*('✏️ Rancangan Anggaran'!Q6:Q155)) | F14: =IF(D19<>0,D14/D19,0) | G14: =IF(D14>0,E14/D14,0)
A15: 11 | B15: 11 | C15: Kegiatan Peningkatan Kompetensi Keahlian | D15: =SUMPRODUCT(('✏️ Rancangan Anggaran'!B6:B155=B15)*('✏️ Rancangan Anggaran'!L6:L155)) | E15: =SUMPRODUCT(('✏️ Rancangan Anggaran'!B6:B155=B15)*('✏️ Rancangan Anggaran'!K6:K155="BOSP")*('✏️ Rancangan Anggaran'!Q6:Q155)) | F15: =IF(D19<>0,D15/D19,0) | G15: =IF(D15>0,E15/D15,0)
A16: 12 | B16: 12 | C16: Layanan Bantuan Siswa (Afirmasi) | D16: =SUMPRODUCT(('✏️ Rancangan Anggaran'!B6:B155=B16)*('✏️ Rancangan Anggaran'!L6:L155)) | E16: =SUMPRODUCT(('✏️ Rancangan Anggaran'!B6:B155=B16)*('✏️ Rancangan Anggaran'!K6:K155="BOSP")*('✏️ Rancangan Anggaran'!Q6:Q155)) | F16: =IF(D19<>0,D16/D19,0) | G16: =IF(D16>0,E16/D16,0)
A17: 13 | B17: 13 | C17: Pemberdayaan Masyarakat Sekitar Sekolah | D17: =SUMPRODUCT(('✏️ Rancangan Anggaran'!B6:B155=B17)*('✏️ Rancangan Anggaran'!L6:L155)) | E17: =SUMPRODUCT(('✏️ Rancangan Anggaran'!B6:B155=B17)*('✏️ Rancangan Anggaran'!K6:K155="BOSP")*('✏️ Rancangan Anggaran'!Q6:Q155)) | F17: =IF(D19<>0,D17/D19,0) | G17: =IF(D17>0,E17/D17,0)
A18: TOTAL | D18: =SUM(D5:D17) | E18: =SUM(E5:E17) | F18: =IF(D18>0,E18/D18,0)

Sheet 📊 Rekap BOPD
A1: REKAPITULASI ANGGARAN — BOPD
A2: SMA Negeri 1 Cigalontang | Tahun Anggaran 2026 | Dana: BOPD
A4: No | B4: Kode | C4: Nama Kegiatan | D4: Rencana BOPD (Rp) | E4: Realisasi BOPD (Rp) | F4: % Rencana | G4: % Realisasi
A5: 1 | B5: 1 | C5: Penerimaan Peserta Didik Baru | D5: =SUMPRODUCT(('✏️ Rancangan Anggaran'!B6:B155=B5)*('✏️ Rancangan Anggaran'!M6:M155)) | E5: =SUMPRODUCT(('✏️ Rancangan Anggaran'!B6:B155=B5)*('✏️ Rancangan Anggaran'!K6:K155="BOPD")*('✏️ Rancangan Anggaran'!Q6:Q155)) | F5: =IF(D19<>0,D5/D19,0) | G5: =IF(D5>0,E5/D5,0)
A6: 2 | B6: 2 | C6: Pengembangan Perpustakaan | D6: =SUMPRODUCT(('✏️ Rancangan Anggaran'!B6:B155=B6)*('✏️ Rancangan Anggaran'!M6:M155)) | E6: =SUMPRODUCT(('✏️ Rancangan Anggaran'!B6:B155=B6)*('✏️ Rancangan Anggaran'!K6:K155="BOPD")*('✏️ Rancangan Anggaran'!Q6:Q155)) | F6: =IF(D19<>0,D6/D19,0) | G6: =IF(D6>0,E6/D6,0)
A7: 3 | B7: 3 | C7: Kegiatan Pembelajaran dan Ekstrakurikuler | D7: =SUMPRODUCT(('✏️ Rancangan Anggaran'!B6:B155=B7)*('✏️ Rancangan Anggaran'!M6:M155)) | E7: =SUMPRODUCT(('✏️ Rancangan Anggaran'!B6:B155=B7)*('✏️ Rancangan Anggaran'!K6:K155="BOPD")*('✏️ Rancangan Anggaran'!Q6:Q155)) | F7: =IF(D19<>0,D7/D19,0) | G7: =IF(D7>0,E7/D7,0)
A8: 4 | B8: 4 | C8: Asesmen/Evaluasi Pembelajaran dan Rapor | D8: =SUMPRODUCT(('✏️ Rancangan Anggaran'!B6:B155=B8)*('✏️ Rancangan Anggaran'!M6:M155)) | E8: =SUMPRODUCT(('✏️ Rancangan Anggaran'!B6:B155=B8)*('✏️ Rancangan Anggaran'!K6:K155="BOPD")*('✏️ Rancangan Anggaran'!Q6:Q155)) | F8: =IF(D19<>0,D8/D19,0) | G8: =IF(D8>0,E8/D8,0)
A9: 5 | B9: 5 | C9: Administrasi Sekolah dan Pengelolaan | D9: =SUMPRODUCT(('✏️ Rancangan Anggaran'!B6:B155=B9)*('✏️ Rancangan Anggaran'!M6:M155)) | E9: =SUMPRODUCT(('✏️ Rancangan Anggaran'!B6:B155=B9)*('✏️ Rancangan Anggaran'!K6:K155="BOPD")*('✏️ Rancangan Anggaran'!Q6:Q155)) | F9: =IF(D19<>0,D9/D19,0) | G9: =IF(D9>0,E9/D9,0)
A10: 6 | B10: 6 | C10: Pengembangan Profesi GTK | D10: =SUMPRODUCT(('✏️ Rancangan Anggaran'!B6:B155=B10)*('✏️ Rancangan Anggaran'!M6:M155)) | E10: =SUMPRODUCT(('✏️ Rancangan Anggaran'!B6:B155=B10)*('✏️ Rancangan Anggaran'!K6:K155="BOPD")*('✏️ Rancangan Anggaran'!Q6:Q155)) | F10: =IF(D19<>0,D10/D19,0) | G10: =IF(D10>0,E10/D10,0)
A11: 7 | B11: 7 | C11: Langganan Daya dan Jasa | D11: =SUMPRODUCT(('✏️ Rancangan Anggaran'!B6:B155=B11)*('✏️ Rancangan Anggaran'!M6:M155)) | E11: =SUMPRODUCT(('✏️ Rancangan Anggaran'!B6:B155=B11)*('✏️ Rancangan Anggaran'!K6:K155="BOPD")*('✏️ Rancangan Anggaran'!Q6:Q155)) | F11: =IF(D19<>0,D11/D19,0) | G11: =IF(D11>0,E11/D11,0)
A12: 8 | B12: 8 | C12: Pemeliharaan Sarana dan Prasarana | D12: =SUMPRODUCT(('✏️ Rancangan Anggaran'!B6:B155=B12)*('✏️ Rancangan Anggaran'!M6:M155)) | E12: =SUMPRODUCT(('✏️ Rancangan Anggaran'!B6:B155=B12)*('✏️ Rancangan Anggaran'!K6:K155="BOPD")*('✏️ Rancangan Anggaran'!Q6:Q155)) | F12: =IF(D19<>0,D12/D19,0) | G12: =IF(D12>0,E12/D12,0)
A13: 9 | B13: 9 | C13: Penyediaan Alat Multi Media Pembelajaran | D13: =SUMPRODUCT(('✏️ Rancangan Anggaran'!B6:B155=B13)*('✏️ Rancangan Anggaran'!M6:M155)) | E13: =SUMPRODUCT(('✏️ Rancangan Anggaran'!B6:B155=B13)*('✏️ Rancangan Anggaran'!K6:K155="BOPD")*('✏️ Rancangan Anggaran'!Q6:Q155)) | F13: =IF(D19<>0,D13/D19,0) | G13: =IF(D13>0,E13/D13,0)
A14: 10 | B14: 10 | C14: Pembayaran Honor | D14: =SUMPRODUCT(('✏️ Rancangan Anggaran'!B6:B155=B14)*('✏️ Rancangan Anggaran'!M6:M155)) | E14: =SUMPRODUCT(('✏️ Rancangan Anggaran'!B6:B155=B14)*('✏️ Rancangan Anggaran'!K6:K155="BOPD")*('✏️ Rancangan Anggaran'!Q6:Q155)) | F14: =IF(D19<>0,D14/D19,0) | G14: =IF(D14>0,E14/D14,0)
A15: 11 | B15: 11 | C15: Kegiatan Peningkatan Kompetensi Keahlian | D15: =SUMPRODUCT(('✏️ Rancangan Anggaran'!B6:B155=B15)*('✏️ Rancangan Anggaran'!M6:M155)) | E15: =SUMPRODUCT(('✏️ Rancangan Anggaran'!B6:B155=B15)*('✏️ Rancangan Anggaran'!K6:K155="BOPD")*('✏️ Rancangan Anggaran'!Q6:Q155)) | F15: =IF(D19<>0,D15/D19,0) | G15: =IF(D15>0,E15/D15,0)
A16: 12 | B16: 12 | C16: Layanan Bantuan Siswa (Afirmasi) | D16: =SUMPRODUCT(('✏️ Rancangan Anggaran'!B6:B155=B16)*('✏️ Rancangan Anggaran'!M6:M155)) | E16: =SUMPRODUCT(('✏️ Rancangan Anggaran'!B6:B155=B16)*('✏️ Rancangan Anggaran'!K6:K155="BOPD")*('✏️ Rancangan Anggaran'!Q6:Q155)) | F16: =IF(D19<>0,D16/D19,0) | G16: =IF(D16>0,E16/D16,0)
A17: 13 | B17: 13 | C17: Pemberdayaan Masyarakat Sekitar Sekolah | D17: =SUMPRODUCT(('✏️ Rancangan Anggaran'!B6:B155=B17)*('✏️ Rancangan Anggaran'!M6:M155)) | E17: =SUMPRODUCT(('✏️ Rancangan Anggaran'!B6:B155=B17)*('✏️ Rancangan Anggaran'!K6:K155="BOPD")*('✏️ Rancangan Anggaran'!Q6:Q155)) | F17: =IF(D19<>0,D17/D19,0) | G17: =IF(D17>0,E17/D17,0)
A18: TOTAL | D18: =SUM(D5:D17) | E18: =SUM(E5:E17) | F18: =IF(D18>0,E18/D18,0)

Sheet 📈 Rekap Gabungan
A1: REKAPITULASI GABUNGAN ANGGARAN SEKOLAH
A2: SMA Negeri 1 Cigalontang | Tahun Anggaran 2026
A4: Ringkasan Dana | D4: Alokasi (Rp) | E4: Rencana (Rp) | F4: Realisasi (Rp) | G4: Sisa Rencana (Rp) | H4: % Realisasi
A5: BOSP | D5: ='⚙ Pengaturan'!E15 | E5: ='📊 Rekap BOSP'!D18 | F5: ='📊 Rekap BOSP'!E18 | G5: =E5-F5 | H5: =IF(E5>0,F5/E5,0)
A6: BOPD | D6: ='⚙ Pengaturan'!E16 | E6: ='📊 Rekap BOPD'!D18 | F6: ='📊 Rekap BOPD'!E18 | G6: =E6-F6 | H6: =IF(E6>0,F6/E6,0)
A7: GRAND TOTAL | D7: =SUM(D5:D6) | E7: =SUM(E5:E6) | F7: =SUM(F5:F6) | G7: =SUM(G5:G6) | H7: =IF(E7>0,F7/E7,0)
A9: Rekapitulasi per Komponen Kegiatan
A10: No | B10: Kode | C10: Nama Kegiatan | D10: Rencana BOSP (Rp) | E10: Rencana BOPD (Rp) | F10: Total Rencana (Rp) | G10: Realisasi (Rp) | H10: % Realisasi
A11: 1 | B11: 1 | C11: Penerimaan Peserta Didik Baru | D11: ='📊 Rekap BOSP'!D5 | E11: ='📊 Rekap BOPD'!D5 | F11: =D11+E11 | G11: ='📊 Rekap BOSP'!E5+'📊 Rekap BOPD'!E5 | H11: =IF(F11>0,G11/F11,0)
A12: 2 | B12: 2 | C12: Pengembangan Perpustakaan | D12: ='📊 Rekap BOSP'!D6 | E12: ='📊 Rekap BOPD'!D6 | F12: =D12+E12 | G12: ='📊 Rekap BOSP'!E6+'📊 Rekap BOPD'!E6 | H12: =IF(F12>0,G12/F12,0)
A13: 3 | B13: 3 | C13: Kegiatan Pembelajaran dan Ekstrakurikuler | D13: ='📊 Rekap BOSP'!D7 | E13: ='📊 Rekap BOPD'!D7 | F13: =D13+E13 | G13: ='📊 Rekap BOSP'!E7+'📊 Rekap BOPD'!E7 | H13: =IF(F13>0,G13/F13,0)
A14: 4 | B14: 4 | C14: Asesmen/Evaluasi Pembelajaran dan Rapor | D14: ='📊 Rekap BOSP'!D8 | E14: ='📊 Rekap BOPD'!D8 | F14: =D14+E14 | G14: ='📊 Rekap BOSP'!E8+'📊 Rekap BOPD'!E8 | H14: =IF(F14>0,G14/F14,0)
A15: 5 | B15: 5 | C15: Administrasi Sekolah dan Pengelolaan | D15: ='📊 Rekap BOSP'!D9 | E15: ='📊 Rekap BOPD'!D9 | F15: =D15+E15 | G15: ='📊 Rekap BOSP'!E9+'📊 Rekap BOPD'!E9 | H15: =IF(F15>0,G15/F15,0)
A16: 6 | B16: 6 | C16: Pengembangan Profesi GTK | D16: ='📊 Rekap BOSP'!D10 | E16: ='📊 Rekap BOPD'!D10 | F16: =D16+E16 | G16: ='📊 Rekap BOSP'!E10+'📊 Rekap BOPD'!E10 | H16: =IF(F16>0,G16/F16,0)
A17: 7 | B17: 7 | C17: Langganan Daya dan Jasa | D17: ='📊 Rekap BOSP'!D11 | E17: ='📊 Rekap BOPD'!D11 | F17: =D17+E17 | G17: ='📊 Rekap BOSP'!E11+'📊 Rekap BOPD'!E11 | H17: =IF(F17>0,G17/F17,0)
A18: 8 | B18: 8 | C18: Pemeliharaan Sarana dan Prasarana | D18: ='📊 Rekap BOSP'!D12 | E18: ='📊 Rekap BOPD'!D12 | F18: =D18+E18 | G18: ='📊 Rekap BOSP'!E12+'📊 Rekap BOPD'!E12 | H18: =IF(F18>0,G18/F18,0)
A19: 9 | B19: 9 | C19: Penyediaan Alat Multi Media Pembelajaran | D19: ='📊 Rekap BOSP'!D13 | E19: ='📊 Rekap BOPD'!D13 | F19: =D19+E19 | G19: ='📊 Rekap BOSP'!E13+'📊 Rekap BOPD'!E13 | H19: =IF(F19>0,G19/F19,0)
A20: 10 | B20: 10 | C20: Pembayaran Honor | D20: ='📊 Rekap BOSP'!D14 | E20: ='📊 Rekap BOPD'!D14 | F20: =D20+E20 | G20: ='📊 Rekap BOSP'!E14+'📊 Rekap BOPD'!E14 | H20: =IF(F20>0,G20/F20,0)
A21: 11 | B21: 11 | C21: Kegiatan Peningkatan Kompetensi Keahlian | D21: ='📊 Rekap BOSP'!D15 | E21: ='📊 Rekap BOPD'!D15 | F21: =D21+E21 | G21: ='📊 Rekap BOSP'!E15+'📊 Rekap BOPD'!E15 | H21: =IF(F21>0,G21/F21,0)
A22: 12 | B22: 12 | C22: Layanan Bantuan Siswa (Afirmasi) | D22: ='📊 Rekap BOSP'!D16 | E22: ='📊 Rekap BOPD'!D16 | F22: =D22+E22 | G22: ='📊 Rekap BOSP'!E16+'📊 Rekap BOPD'!E16 | H22: =IF(F22>0,G22/F22,0)
A23: 13 | B23: 13 | C23: Pemberdayaan Masyarakat Sekitar Sekolah | D23: ='📊 Rekap BOSP'!D17 | E23: ='📊 Rekap BOPD'!D17 | F23: =D23+E23 | G23: ='📊 Rekap BOSP'!E17+'📊 Rekap BOPD'!E17 | H23: =IF(F23>0,G23/F23,0)
A24: TOTAL | D24: =SUM(D11:D23) | E24: =SUM(E11:E23) | F24: =SUM(F11:F23) | G24: =SUM(G11:G23) | H24: =IF(F24>0,G24/F24,0)

Sheet 🖨️ Laporan KS
A1: PEMERINTAH PROVINSI JAWA BARAT
A2: DINAS PENDIDIKAN
A3: SMA NEGERI 1 CIGALONTANG
A4: Alamat: Jl. Cigalontang, Kec. Cigalontang, Kab. Tasikmalaya, Jawa Barat
A7: LAPORAN RENCANA KEGIATAN DAN ANGGARAN SEKOLAH (RKAS)
A8: Tahun Anggaran 2026
A10: I. RINGKASAN ALOKASI DAN RENCANA PENGGUNAAN DANA
A11: No | B11: Sumber Dana | C11: Alokasi (Rp) | D11: Rencana (Rp) | E11: Realisasi (Rp) | F11: Sisa (Rp) | G11: % Realisasi
A12: 1 | B12: BOSP | C12: ='⚙ Pengaturan'!E15 | D12: ='📊 Rekap BOSP'!D18 | E12: ='📊 Rekap BOSP'!E18 | F12: =D12-E12 | G12: =IF(D12>0,E12/D12,0)
A13: 2 | B13: BOPD | C13: ='⚙ Pengaturan'!E16 | D13: ='📊 Rekap BOPD'!D18 | E13: ='📊 Rekap BOPD'!E18 | F13: =D13-E13 | G13: =IF(D13>0,E13/D13,0)
A14: TOTAL | C14: =SUM(C12:C13) | D14: =SUM(D12:D13) | E14: =SUM(E12:E13) | F14: =SUM(F12:F13) | G14: =IF(D14>0,E14/D14,0)
A16: II. RINCIAN RENCANA PER KOMPONEN KEGIATAN
A17: No | B17: Kode | C17: Komponen Kegiatan | D17: Rencana BOSP | E17: Rencana BOPD | F17: Total Rencana | G17: % dari Total
A18: 1 | B18: 1 | C18: Penerimaan Peserta Didik Baru | D18: ='📊 Rekap BOSP'!D5 | E18: ='📊 Rekap BOPD'!D5 | F18: =D18+E18 | G18: =IF('📈 Rekap Gabungan'!F24>0,F18/'📈 Rekap Gabungan'!F24,0)
A19: 2 | B19: 2 | C19: Pengembangan Perpustakaan | D19: ='📊 Rekap BOSP'!D6 | E19: ='📊 Rekap BOPD'!D6 | F19: =D19+E19 | G19: =IF('📈 Rekap Gabungan'!F24>0,F19/'📈 Rekap Gabungan'!F24,0)
A20: 3 | B20: 3 | C20: Kegiatan Pembelajaran dan Ekstrakurikuler | D20: ='📊 Rekap BOSP'!D7 | E20: ='📊 Rekap BOPD'!D7 | F20: =D20+E20 | G20: =IF('📈 Rekap Gabungan'!F24>0,F20/'📈 Rekap Gabungan'!F24,0)
A21: 4 | B21: 4 | C21: Asesmen/Evaluasi Pembelajaran dan Rapor | D21: ='📊 Rekap BOSP'!D8 | E21: ='📊 Rekap BOPD'!D8 | F21: =D21+E21 | G21: =IF('📈 Rekap Gabungan'!F24>0,F21/'📈 Rekap Gabungan'!F24,0)
A22: 5 | B22: 5 | C22: Administrasi Sekolah dan Pengelolaan | D22: ='📊 Rekap BOSP'!D9 | E22: ='📊 Rekap BOPD'!D9 | F22: =D22+E22 | G22: =IF('📈 Rekap Gabungan'!F24>0,F22/'📈 Rekap Gabungan'!F24,0)
A23: 6 | B23: 6 | C23: Pengembangan Profesi GTK | D23: ='📊 Rekap BOSP'!D10 | E23: ='📊 Rekap BOPD'!D10 | F23: =D23+E23 | G23: =IF('📈 Rekap Gabungan'!F24>0,F23/'📈 Rekap Gabungan'!F24,0)
A24: 7 | B24: 7 | C24: Langganan Daya dan Jasa | D24: ='📊 Rekap BOSP'!D11 | E24: ='📊 Rekap BOPD'!D11 | F24: =D24+E24 | G24: =IF('📈 Rekap Gabungan'!F24>0,F24/'📈 Rekap Gabungan'!F24,0)
A25: 8 | B25: 8 | C25: Pemeliharaan Sarana dan Prasarana | D25: ='📊 Rekap BOSP'!D12 | E25: ='📊 Rekap BOPD'!D12 | F25: =D25+E25 | G25: =IF('📈 Rekap Gabungan'!F24>0,F25/'📈 Rekap Gabungan'!F24,0)
A26: 9 | B26: 9 | C26: Penyediaan Alat Multi Media Pembelajaran | D26: ='📊 Rekap BOSP'!D13 | E26: ='📊 Rekap BOPD'!D13 | F26: =D26+E26 | G26: =IF('📈 Rekap Gabungan'!F24>0,F26/'📈 Rekap Gabungan'!F24,0)
A27: 10 | B27: 10 | C27: Pembayaran Honor | D27: ='📊 Rekap BOSP'!D14 | E27: ='📊 Rekap BOPD'!D14 | F27: =D27+E27 | G27: =IF('📈 Rekap Gabungan'!F24>0,F27/'📈 Rekap Gabungan'!F24,0)
A28: 11 | B28: 11 | C28: Kegiatan Peningkatan Kompetensi Keahlian | D28: ='📊 Rekap BOSP'!D15 | E28: ='📊 Rekap BOPD'!D15 | F28: =D28+E28 | G28: =IF('📈 Rekap Gabungan'!F24>0,F28/'📈 Rekap Gabungan'!F24,0)
A29: 12 | B29: 12 | C29: Layanan Bantuan Siswa (Afirmasi) | D29: ='📊 Rekap BOSP'!D16 | E29: ='📊 Rekap BOPD'!D16 | F29: =D29+E29 | G29: =IF('📈 Rekap Gabungan'!F24>0,F29/'📈 Rekap Gabungan'!F24,0)
A30: 13 | B30: 13 | C30: Pemberdayaan Masyarakat Sekitar Sekolah | D30: ='📊 Rekap BOSP'!D17 | E30: ='📊 Rekap BOPD'!D17 | F30: =D30+E30 | G30: =IF('📈 Rekap Gabungan'!F24>0,F30/'📈 Rekap Gabungan'!F24,0)
A31: TOTAL | D31: =SUM(D18:D30) | E31: =SUM(E18:E30) | F31: =SUM(F18:F30) | G31: 100.0%
A34: Bendahara BOSP / BOPD, | E34: Cigalontang, 17 April 2026
E35: Kepala Sekolah,
A39: (.....................................) | E39: (.....................................)
A40: NIP. ............................. | E40: NIP. .............................

Sheet ℹ️ Petunjuk
B2: PETUNJUK PENGGUNAAN APLIKASI RANCANGAN ANGGARAN ARKAS v2
B4: ⚙️ 1. PENGATURAN
B5: • | C5: Buka sheet "⚙ Pengaturan" — isi data sekolah, nama pejabat, dan paling penting: Total Alokasi BOSP (E15) dan BOPD (E16).
B6: • | C6: Nilai alokasi ini digunakan secara otomatis oleh sheet Kontrol Batas BOSP untuk menghitung peringatan.
B8: 📋 2. REFERENSI KODE
B9: • | C9: "📋 Kode Kegiatan" → 13 komponen kegiatan ARKAS (Permendikbudristek No. 2/2022).
B10: • | C10: "📂 Kode Rekening" → kode BAS nasional untuk belanja BOSP.
B11: • | C11: "📂 Kode Rekening BOPD Jabar" → kode khusus Provinsi Jawa Barat. Konfirmasi ke operator SIPD Dinas Pendidikan sebelum entri final.
B13: ✏️ 3. MENGISI RANCANGAN ANGGARAN (150 baris)
B14: • | C14: Pilih Kode Kegiatan dari dropdown (kolom B) → isi Nama Kegiatan (kolom C) sesuai.
B15: • | C15: Ketik Kode Rekening (kolom D) dari sheet referensi → isi Uraian Rekening (E) dan Uraian Rincian (F).
B16: • | C16: Isi Volume, Satuan, Harga Satuan → kolom Jumlah terisi OTOMATIS.
B17: • | C17: Pilih Sumber Dana: BOSP → isi Alokasi BOSP (L); BOPD → isi Alokasi BOPD (M).
B18: • | C18: Kolom Realisasi (Q): diisi setelah kegiatan terlaksana. Kolom % Realisasi & Sisa terisi OTOMATIS.
B19: • | C19: Pilih Status Realisasi dari dropdown: Belum Direalisasi / Sebagian / Selesai.
B21: ⚠️ 4. KONTROL BATAS BOSP (otomatis)
B22: • | C22: Buka sheet "⚠️ Kontrol Batas BOSP" setelah mengisi Rancangan Anggaran.
B23: • | C23: ✅ Hijau "Aman/Terpenuhi" = alokasi sesuai regulasi.
B24: • | C24: ⛔ Merah "MELEBIHI BATAS" = Honor (Kode 10) melebihi 50% total BOSP — harus dikoreksi.
B25: • | C25: ⚠️ Jingga "DI BAWAH BATAS" = komponen penting (Buku/Pembelajaran) di bawah minimum yang disarankan.
B26: • | C26: Pastikan tidak ada item di tabel LARANGAN yang dianggarkan dari BOSP.
B28: 📊 5. REKAP DAN LAPORAN
B29: • | C29: "📊 Rekap BOSP" dan "📊 Rekap BOPD" → rekap per komponen, otomatis dari Rancangan.
B30: • | C30: "📈 Rekap Gabungan" → perbandingan BOSP + BOPD, termasuk persentase realisasi.
B31: • | C31: "🖨️ Laporan KS" → siap cetak ke Kepala Sekolah. Cetak via File → Print → pilih sheet ini.
B33: 💾 6. TIPS UMUM
B34: • | C34: Simpan rutin (Ctrl+S). Untuk backup, simpan salinan dengan nama: ARKAS_YYYY_revisi_Bulan.xlsx.
B35: • | C35: Jangan mengubah nama sheet — formula antar sheet bergantung nama tersebut.
B36: • | C36: Jumlah baris dapat ditambah dengan mengedit konstanta JUMLAH_BARIS di buat-arkas.js dan jalankan ulang.
B37: • | C37: File ini hanya alat bantu PERANCANGAN. Entri final tetap di aplikasi ARKAS resmi (arkas.kemdikbud.go.id).
